Workbook

Sheet Contents
A1: Bolt Technology OÜ - Draft Valuation Model
A2: Source: Bolt Technology OÜ Consolidated Annual Report 2025 (AS PricewaterhouseCoopers audit)
A4: ' | B4: Contents
A21: ' | B21: Model Key
B23: i_ | C23: Inputs & Assumptions | D23: Hardcoded data, historical figures, and model assumptions
B24: c_ | C24: Calculations | D24: Dynamic formulas and cross-sheet links
B25: o_ | C25: Valuation Outputs | D25: Blended pre-money enterprise and equity valuations
B26: >> | C26: Section dividers | D26: Navigation tabs separating Input, Calcs and Output sections
B28: Note: All sheets are protected other than input assumptions which drive valuation outputs; password held by the model owner. Please edit only assumption cells on i_Inputs (cols D:J).
B30: Disclaimer: This model is a draft prepared for illustrative and analytical purposes only. Forward-looking figures (2026E-2028E), valuation multiples, and implied share prices are based on assumptions and estimates that are inherently uncertain and may differ materially from actual results. Historical figures are extracted from the Bolt Technology OÜ Consolidated Annual Report 2025 and have not been independently verified. Nothing in this model constitutes investment, financial, legal or tax advice, an offer or solicitation to buy or sell any security, or a recommendation regarding any IPO. No output should be relied upon for any investment decision. The author accepts no liability for any loss arising from use of, or reliance on, this model.
A32: ' | B32: End of Worksheet

Sheet Output>>

Sheet o_Dashboard
A1: =Contents!$A1 -> Bolt Technology OÜ - Draft Valuation Model
A2: =Contents!$A2 -> Source: Bolt Technology OÜ Consolidated Annual Report 2025 (AS PricewaterhouseCoopers audit)
A3: (EUR '000 unless stated)
A5: ' | B5: KEY VALUATION OUTPUTS
B7: =o_Valuation!B56 -> Target Price with 7% IPO Discount
B8: =o_Valuation!D56 -> 141.75019
B10: =o_Valuation!B50 -> Blended Target Pre-Money Equity Value
B11: =o_Valuation!D50 -> 4758995.9
A13: ' | B13: FINANCIAL SUMMARY
B15: Metric | C15: =o_FS!E4 -> 2024A | D15: =o_FS!F4 -> 2025A | E15: =o_FS!G4 -> 2026E | F15: =o_FS!H4 -> 2027E | G15: =o_FS!I4 -> 2028E
C16: =o_FS!E5 -> Actual | D16: =o_FS!F5 -> Actual | E16: =o_FS!G5 -> Estimate | F16: =o_FS!H5 -> Estimate | G16: =o_FS!I5 -> Estimate
B17: =o_FS!B8 -> Sales revenue | C17: =o_FS!E8 -> 1992054 | D17: =o_FS!F8 -> 2270854 | E17: =o_FS!G8 -> 2563281.2 | F17: =o_FS!H8 -> 2867849.2 | G17: =o_FS!I8 -> 3172646.9
B18: =c_FS!B12 -> YoY revenue growth rate (%) | C18: =c_FS!E12 -> 0 | D18: =c_FS!F12 -> 0.13995605 | E18: =c_FS!G12 -> 0.12877413 | F18: =c_FS!H12 -> 0.11881955 | G18: =c_FS!I12 -> 0.10628096
B19: =o_FS!B11 -> Gross Margin % | C19: =o_FS!E11 -> 0.56603737 | D19: =o_FS!F11 -> 0.63395269 | E19: =o_FS!G11 -> 0.645 | F19: =o_FS!H11 -> 0.65 | G19: =o_FS!I11 -> 0.655
B20: =o_FS!B20 -> EBITDA | C20: =o_FS!E20 -> -30298 | D20: =o_FS!F20 -> 76672 | E20: =o_FS!G20 -> 92570.719 | F20: =o_FS!H20 -> 183438.26 | G20: =o_FS!I20 -> 292518.06
B21: =o_FS!B21 -> EBITDA Margin % | C21: =o_FS!E21 -> -0.015209427 | D21: =o_FS!F21 -> 0.033763509 | E21: =o_FS!G21 -> 0.036114148 | F21: =o_FS!H21 -> 0.063963706 | G21: =o_FS!I21 -> 0.092200002
B22: =o_FS!B17 -> Operating Profit / (Loss) (EBIT) | C22: =o_FS!E17 -> -87735 | D22: =o_FS!F17 -> 19454 | E22: =o_FS!G17 -> 38449.219 | F22: =o_FS!H17 -> 129053.21 | G22: =o_FS!I17 -> 237948.52
B23: =o_FS!B26 -> Net Profit / (Loss) for the Period | C23: =o_FS!E26 -> -102594 | D23: =o_FS!F26 -> 920 | E23: =o_FS!G26 -> 29347.712 | F23: =o_FS!H26 -> 101054.31 | G23: =o_FS!I26 -> 187892.76
B24: =o_FS!B35 -> Free Cash Flow to Firm (FCFF) | C24: =o_FS!E35 -> -34486.3 | D24: =o_FS!F35 -> 48622.12 | E24: =o_FS!G35 -> 39064.745 | F24: =o_FS!H35 -> 91447.671 | G24: =o_FS!I35 -> 188373.01
B25: =o_FS!B39 -> Closing cash & cash equivalents | C25: =o_FS!E39 -> 342247 | D25: =o_FS!F39 -> 357038 | E25: =o_FS!G39 -> 384660.83 | F25: =o_FS!H39 -> 465465.84 | G25: =o_FS!I39 -> 644276.37
B26: =o_FS!B42 -> Net Cash / (Net Debt) Position | C26: =o_FS!E42 -> 104873 | D26: =o_FS!F42 -> 249474 | E26: =o_FS!G42 -> 287896.07 | F26: =o_FS!H42 -> 379736.54 | G26: =o_FS!I42 -> 570402.46
B28: ASSUMPTIONS
B29: =i_Inputs!B54 -> Weighted Average Cost of Capital (WACC) | C29: =i_Inputs!D54 -> 0.105
B30: =i_Inputs!B55 -> Terminal Growth Rate (DCF) | C30: =i_Inputs!D55 -> 0.04
B31: =i_Inputs!B56 -> Target EV / Sales Multiple (Public Comps) | C31: =i_Inputs!D56 -> 2.5
B32: =i_Inputs!B57 -> Target EV / EBITDA Multiple (Public Comps) | C32: =i_Inputs!D57 -> 20
B33: =i_Inputs!B49 -> Effective corporate tax rate | C33: =i_Inputs!D49 -> 0.22
B34: =i_Inputs!B59 -> IPO Underwriter Discount / Spread | C34: =i_Inputs!D59 -> 0.07
B35: =i_Inputs!B60 -> Target Primary Capital Raised at IPO | C35: =i_Inputs!D60 -> 500000
B37: CAPITAL STRUCTURE 2025A
B38: Shares Outstanding (Diluted Post-Conversion) | C38: =i_Historical!F49 -> 31223
B39: Closing cash | C39: =o_FS!F39 -> 357038
B40: Funded debt | C40: =o_FS!F40 -> -527
B41: Lease liabilities | C41: =o_FS!F41 -> -107037
B42: Undrawn Syndicated Credit Line | C42: =i_Historical!F55 -> 220000
A64: ' | B64: End of Worksheet

Sheet o_Valuation
A1: =Contents!$A1 -> Bolt Technology OÜ - Draft Valuation Model
A2: =Contents!$A2 -> Source: Bolt Technology OÜ Consolidated Annual Report 2025 (AS PricewaterhouseCoopers audit)
E4: =o_FS!E4 -> 2024A | F4: =o_FS!F4 -> 2025A | G4: =o_FS!G4 -> 2026E | H4: =o_FS!H4 -> 2027E | I4: =o_FS!I4 -> 2028E
B5: Valuation Methodology / Metric | C5: Unit | E5: =o_FS!E5 -> Actual | F5: =o_FS!F5 -> Actual | G5: =o_FS!G5 -> Estimate | H5: =o_FS!H5 -> Estimate | I5: =o_FS!I5 -> Estimate
A6: ' | B6: DCF Valuation
B8: Weighted Average Cost of Capital (WACC) | C8: % | D8: =i_Inputs!$D$54 -> 0.105
B9: Terminal Growth Rate (g) | C9: % | D9: =i_Inputs!$D$55 -> 0.04
B10: Mid-year Discounting Convention (period offset) | C10: Years | D10: =i_Inputs!$D$62 -> 0.5
B12: Forecast period flag | C12: Flag | E12: =IF(E$5="Estimate",1,0) -> 0 | F12: =IF(F$5="Estimate",1,0) -> 0 | G12: =IF(G$5="Estimate",1,0) -> 1 | H12: =IF(H$5="Estimate",1,0) -> 1 | I12: =IF(I$5="Estimate",1,0) -> 1
B13: Discount period (t) | C13: Years | E13: =IF(E12=1,SUM($E12:E12)-$D$10,0) -> 0 | F13: =IF(F12=1,SUM($E12:F12)-$D$10,0) -> 0 | G13: =IF(G12=1,SUM($E12:G12)-$D$10,0) -> 0.5 | H13: =IF(H12=1,SUM($E12:H12)-$D$10,0) -> 1.5 | I13: =IF(I12=1,SUM($E12:I12)-$D$10,0) -> 2.5
B14: Terminal year flag | C14: Flag | E14: =IF(AND(E12=1,E13=MAX($E$13:$I$13)),1,0) -> 0 | F14: =IF(AND(F12=1,F13=MAX($E$13:$I$13)),1,0) -> 0 | G14: =IF(AND(G12=1,G13=MAX($E$13:$I$13)),1,0) -> 0 | H14: =IF(AND(H12=1,H13=MAX($E$13:$I$13)),1,0) -> 0 | I14: =IF(AND(I12=1,I13=MAX($E$13:$I$13)),1,0) -> 1
B16: Unlevered FCF | C16: EUR '000 | E16: =o_FS!E35 -> -34486.3 | F16: =o_FS!F35 -> 48622.12 | G16: =o_FS!G35 -> 39064.745 | H16: =o_FS!H35 -> 91447.671 | I16: =o_FS!I35 -> 188373.01
B17: Discount factor | C17: x | E17: =IF(E12=1,1/(1+$D$8)^E13,0) -> 0 | F17: =IF(F12=1,1/(1+$D$8)^F13,0) -> 0 | G17: =IF(G12=1,1/(1+$D$8)^G13,0) -> 0.95130299 | H17: =IF(H12=1,1/(1+$D$8)^H13,0) -> 0.86090768 | I17: =IF(I12=1,1/(1+$D$8)^I13,0) -> 0.77910197
B18: PV of Unlevered FCF | C18: EUR '000 | D18: =SUM(E18:I18) -> 262652.19 | E18: =E16*E17 -> 0 | F18: =F16*F17 -> 0 | G18: =G16*G17 -> 37162.408 | H18: =H16*H17 -> 78728.002 | I18: =I16*I17 -> 146761.78
B20: Terminal Year Unlevered FCF | C20: EUR '000 | D20: =SUMPRODUCT(E14:I14,E16:I16) -> 188373.01
B21: Terminal Value (Gordon Growth) | C21: EUR '000 | D21: =D20*(1+D9)/(D8-D9) -> 3013968.1
B22: Present Value of Terminal Value | C22: EUR '000 | D22: =D21*SUMPRODUCT(E14:I14,E17:I17) -> 2348188.5
B23: Enterprise Value (DCF Method) | C23: EUR '000 | D23: =D18+D22 -> 2610840.7
B24: Add: 2025A Cash and Cash Equivalents | C24: EUR '000 | D24: =i_Historical!F30 -> 357038
B25: Less: 2025A Funded Loan Debt | C25: EUR '000 | D25: =-i_Historical!F39 -> -527
B26: Less: 2025A Lease Obligations | C26: EUR '000 | D26: =-i_Historical!F40 -> -107037
B27: Implied Equity Value (DCF Method) | C27: EUR '000 | D27: =D23+D24+D25+D26 -> 2860314.7
B28: Diluted Shares Outstanding | C28: Thousands | D28: =i_Inputs!$D$58 -> 31223
B29: Implied Share Price (DCF) | C29: EUR / Share | D29: =D27/D28 -> 91.609221
A31: ' | B31: Comparable Company Analysis
B33: 2026E Consolidated Sales Revenue (forward-looking) | C33: EUR '000 | D33: =o_FS!G8 -> 2563281.2
B34: EV / Sales Multiple Benchmark | C34: x | D34: =i_Inputs!$D$56 -> 2.5
B35: Implied Enterprise Value (EV / Sales) | C35: EUR '000 | D35: =D33*D34 -> 6408203.1
B36: Implied Equity Value (EV / Sales) | C36: EUR '000 | D36: =D35+D24+D25+D26 -> 6657677.1
B37: Implied Share Price (EV / Sales) | C37: EUR / Share | D37: =D36/D28 -> 213.2299
B39: 2026E Adjusted EBITDA (forward-looking) | C39: EUR '000 | D39: =o_FS!G20 -> 92570.719
B40: EV / EBITDA Multiple Benchmark | C40: x | D40: =i_Inputs!$D$57 -> 20
B41: Implied Enterprise Value (EV / EBITDA) | C41: EUR '000 | D41: =D39*D40 -> 1851414.4
B42: Implied Equity Value (EV / EBITDA) | C42: EUR '000 | D42: =D41+D24+D25+D26 -> 2100888.4
B43: Implied Share Price (EV / EBITDA) | C43: EUR / Share | D43: =D42/D28 -> 67.286564
A45: ' | B45: Pre-IPO Valuation Summary
B47: =i_Inputs!B61 -> DCF Weight | C47: =i_Inputs!C61 -> % | D47: =i_Inputs!D61 -> 0.5
B49: Blended Target Pre-Money Enterprise Value | C49: EUR '000 | D49: =D23*$D$47+D35*(1-$D$47) -> 4509521.9
B50: Blended Target Pre-Money Equity Value | C50: EUR '000 | D50: =D49+D24+D25+D26 -> 4758995.9
B52: Target Primary Capital Raised at IPO | C52: EUR '000 | D52: =i_Inputs!$D$60 -> 500000
...

Sheet o_FS
A1: =Contents!$A1 -> Bolt Technology OÜ - Draft Valuation Model
A2: =Contents!$A2 -> Source: Bolt Technology OÜ Consolidated Annual Report 2025 (AS PricewaterhouseCoopers audit)
B4: EUR '000s | E4: =c_FS!E4 -> 2024A | F4: =c_FS!F4 -> 2025A | G4: =c_FS!G4 -> 2026E | H4: =c_FS!H4 -> 2027E | I4: =c_FS!I4 -> 2028E
E5: =c_FS!E5 -> Actual | F5: =c_FS!F5 -> Actual | G5: =c_FS!G5 -> Estimate | H5: =c_FS!H5 -> Estimate | I5: =c_FS!I5 -> Estimate
A6: ' | B6: Consolidated Income Statement
B8: Sales revenue | E8: =c_FS!E11 -> 1992054 | F8: =c_FS!F11 -> 2270854 | G8: =c_FS!G11 -> 2563281.2 | H8: =c_FS!H11 -> 2867849.2 | I8: =c_FS!I11 -> 3172646.9
B9: COGS/ selling expenses | E9: =c_FS!E16 -> -864477 | F9: =c_FS!F16 -> -831240 | G9: =c_FS!G16 -> -909964.84 | H9: =c_FS!H16 -> -1003747.2 | I9: =c_FS!I16 -> -1094563.2
B10: Gross Profit | E10: =SUM(E8:E9) -> 1127577 | F10: =SUM(F8:F9) -> 1439614 | G10: =SUM(G8:G9) -> 1653316.4 | H10: =SUM(H8:H9) -> 1864102 | I10: =SUM(I8:I9) -> 2078083.8
B11: Gross Margin % | E11: =E10/E8 -> 0.56603737 | F11: =F10/F8 -> 0.63395269 | G11: =G10/G8 -> 0.645 | H11: =H10/H8 -> 0.65 | I11: =I10/I8 -> 0.655
B12: Marketing expenses | E12: =c_FS!E18 -> -795513 | F12: =c_FS!F18 -> -1048370 | G12: =c_FS!G18 -> -1153476.6 | H12: =c_FS!H18 -> -1218835.9 | I12: =c_FS!I18 -> -1269058.8
B13: Research and development expenses | E13: =c_FS!E19 -> -107877 | F13: =c_FS!F19 -> -127580 | G13: =c_FS!G19 -> -128164.06 | H13: =c_FS!H19 -> -143392.46 | I13: =c_FS!I19 -> -158632.35
B14: General and administrative expenses | E14: =c_FS!E20 -> -319933 | F14: =c_FS!F20 -> -253032 | G14: =c_FS!G20 -> -307593.75 | H14: =c_FS!H20 -> -344141.9 | I14: =c_FS!I20 -> -380717.63
B15: Other operating expenses | E15: =c_FS!E21 -> -8913 | F15: =c_FS!F21 -> -13131 | G15: =c_FS!G21 -> -51265.625 | H15: =c_FS!H21 -> -57356.984 | I15: =c_FS!I21 -> -63452.939
B16: Other operating income | E16: =c_FS!E22 -> 16924 | F16: =c_FS!F22 -> 21953 | G16: =c_FS!G22 -> 25632.812 | H16: =c_FS!H22 -> 28678.492 | I16: =c_FS!I22 -> 31726.469
B17: Operating Profit / (Loss) (EBIT) | E17: =E10+SUM(E12:E16) -> -87735 | F17: =F10+SUM(F12:F16) -> 19454 | G17: =G10+SUM(G12:G16) -> 38449.219 | H17: =H10+SUM(H12:H16) -> 129053.21 | I17: =I10+SUM(I12:I16) -> 237948.52
B18: Operating Profit Margin % | E18: =E17/E8 -> -0.044042481 | F18: =F17/F8 -> 0.0085668211 | G18: =G17/G8 -> 0.015 | H18: =H17/H8 -> 0.045 | I18: =I17/I8 -> 0.075
B19: Depreciation & amortization (add-back) | E19: =-c_FS!E37 -> 57437 | F19: =-c_FS!F37 -> 57218 | G19: =-c_FS!G37 -> 54121.5 | H19: =-c_FS!H37 -> 54385.05 | I19: =-c_FS!I37 -> 54569.535
B20: EBITDA | E20: =E17+E19 -> -30298 | F20: =F17+F19 -> 76672 | G20: =G17+G19 -> 92570.719 | H20: =H17+H19 -> 183438.26 | I20: =I17+I19 -> 292518.06
B21: EBITDA Margin % | E21: =E20/E8 -> -0.015209427 | F21: =F20/F8 -> 0.033763509 | G21: =G20/G8 -> 0.036114148 | H21: =H20/H8 -> 0.063963706 | I21: =I20/I8 -> 0.092200002
B22: Net financial income / (costs) | E22: =c_FS!E58 -> 1686 | F22: =c_FS!F58 -> -1291 | G22: =c_FS!G58 -> -823.9466 | H22: =c_FS!H58 -> 503.59455 | I22: =c_FS!I58 -> 2939.6296
B23: Fair value adjustments & other | E23: =i_Historical!E23 -> -1951 | F23: =i_Historical!F23 -> -3882 | G23: =i_Inputs!G50 -> 0 | H23: =i_Inputs!H50 -> 0 | I23: =i_Inputs!I50 -> 0
B24: Profit / (Loss) Before Income Tax | E24: =E17+SUM(E22:E23) -> -88000 | F24: =F17+SUM(F22:F23) -> 14281 | G24: =G17+SUM(G22:G23) -> 37625.272 | H24: =H17+SUM(H22:H23) -> 129556.81 | I24: =I17+SUM(I22:I23) -> 240888.15
B25: Corporate income tax expense | E25: =i_Historical!E25 -> -14594 | F25: =i_Historical!F25 -> -13361 | G25: =-MAX(0, G24)*i_Inputs!$D$49 -> -8277.5599 | H25: =-MAX(0, H24)*i_Inputs!$D$49 -> -28502.498 | I25: =-MAX(0, I24)*i_Inputs!$D$49 -> -52995.393
B26: Net Profit / (Loss) for the Period | E26: =SUM(E24:E25) -> -102594 | F26: =SUM(F24:F25) -> 920 | G26: =SUM(G24:G25) -> 29347.712 | H26: =SUM(H24:H25) -> 101054.31 | I26: =SUM(I24:I25) -> 187892.76
B27: Net Profit Margin % | E27: =E26/E8 -> -0.051501616 | F27: =F26/F8 -> 0.00040513393 | G27: =G26/G8 -> 0.011449275 | H27: =H26/H8 -> 0.035236968 | I27: =I26/I8 -> 0.059222712
A29: ' | B29: Free Cash Flow and Cash Balance
B31: NOPAT | E31: =o_FS!E17*(1-i_Inputs!$D$49) -> -68433.3 | F31: =o_FS!F17*(1-i_Inputs!$D$49) -> 15174.12 | G31: =o_FS!G17*(1-i_Inputs!$D$49) -> 29990.391 | H31: =o_FS!H17*(1-i_Inputs!$D$49) -> 100661.51 | I31: =o_FS!I17*(1-i_Inputs!$D$49) -> 185599.85
B32: Add: depreciation & amortization | E32: =o_FS!E19 -> 57437 | F32: =o_FS!F19 -> 57218 | G32: =o_FS!G19 -> 54121.5 | H32: =o_FS!H19 -> 54385.05 | I32: =o_FS!I19 -> 54569.535
B33: Less: capex | E33: =-c_FS!E36 -> -24860 | F33: =-c_FS!F36 -> -49348 | G33: =-c_FS!G36 -> -55000 | H33: =-c_FS!H36 -> -55000 | I33: =-c_FS!I36 -> -55000
B34: Less: change in net working capital | E34: =-(c_FS!E31) -> 1370 | F34: =-(c_FS!F31) -> 25578 | G34: =-c_FS!G31 -> 9952.854 | H34: =-c_FS!H31 -> -8598.8857 | I34: =-c_FS!I31 -> 3203.6257
B35: Free Cash Flow to Firm (FCFF) | E35: =SUM(E31:E34) -> -34486.3 | F35: =SUM(F31:F34) -> 48622.12 | G35: =SUM(G31:G34) -> 39064.745 | H35: =SUM(H31:H34) -> 91447.671 | I35: =SUM(I31:I34) -> 188373.01
B37: Opening cash balance | E37: =D39 -> 325013 | F37: =E39 -> 342247 | G37: =F39 -> 357038 | H37: =G39 -> 384660.83 | I37: =H39 -> 465465.84
B38: Add: net cash generated in period | E38: =i_Historical!E30-E37 -> 17234 | F38: =i_Historical!F30-F37 -> 14791 | G38: =G35+G22*(1-i_Inputs!$D$49)+c_FS!G51+c_FS!G50+c_FS!G44+c_FS!G45 -> 27622.832 | H38: =H35+H22*(1-i_Inputs!$D$49)+c_FS!H51+c_FS!H50+c_FS!H44+c_FS!H45 -> 80805.013 | I38: =I35+I22*(1-i_Inputs!$D$49)+c_FS!I51+c_FS!I50+c_FS!I44+c_FS!I45 -> 178810.52
B39: Closing cash & cash equivalents | D39: =i_Inputs!D47 -> 325013 | E39: =SUM(E37:E38) -> 342247 | F39: =SUM(F37:F38) -> 357038 | G39: =SUM(G37:G38) -> 384660.83 | H39: =SUM(H37:H38) -> 465465.84 | I39: =SUM(I37:I38) -> 644276.37
B40: Less: total funded debt outstanding | E40: =-c_FS!E46 -> -138498 | F40: =-c_FS!F46 -> -527 | G40: =-c_FS!G46 -> 0 | H40: =-c_FS!H46 -> 0 | I40: =-c_FS!I46 -> 0
B41: Less: lease liabilities outstanding | E41: =-c_FS!E52 -> -98876 | F41: =-c_FS!F52 -> -107037 | G41: =-c_FS!G52 -> -96764.766 | H41: =-c_FS!H52 -> -85729.304 | I41: =-c_FS!I52 -> -73873.908
B42: Net Cash / (Net Debt) Position | E42: =SUM(E39:E41) -> 104873 | F42: =SUM(F39:F41) -> 249474 | G42: =SUM(G39:G41) -> 287896.07 | H42: =SUM(H39:H41) -> 379736.54 | I42: =SUM(I39:I41) -> 570402.46
B43: Cash roll-forward check | E43: =E39-E37-E38 -> 0 | F43: =F39-F37-F38 -> 0 | G43: =G39-G37-G38 -> -2.910383e-11 | H43: =H39-H37-H38 -> 0 | I43: =I39-I37-I38 -> 0
A45: ' | B45: End of Worksheet

Sheet Calcs>>

Sheet c_FS
A1: =Contents!$A1 -> Bolt Technology OÜ - Draft Valuation Model
A2: =Contents!$A2 -> Source: Bolt Technology OÜ Consolidated Annual Report 2025 (AS PricewaterhouseCoopers audit)
B4: EUR '000s | E4: =i_Inputs!E4 -> 2024A | F4: =i_Inputs!F4 -> 2025A | G4: =i_Inputs!G4 -> 2026E | H4: =i_Inputs!H4 -> 2027E | I4: =i_Inputs!I4 -> 2028E
E5: =i_Inputs!E5 -> Actual | F5: =i_Inputs!F5 -> Actual | G5: =i_Inputs!G5 -> Estimate | H5: =i_Inputs!H5 -> Estimate | I5: =i_Inputs!I5 -> Estimate
A6: ' | B6: Revenue Breakdown
B8: Ride-hailing revenue | E8: =IF(E$5="Actual",i_Historical!E10,D8*(1+i_Inputs!E8)) -> 1633907 | F8: =IF(F$5="Actual",i_Historical!F10,E8*(1+i_Inputs!F8)) -> 1847432 | G8: =IF(G$5="Actual",i_Historical!G10,F8*(1+i_Inputs!G8)) -> 2069123.8 | H8: =IF(H$5="Actual",i_Historical!H10,G8*(1+i_Inputs!H8)) -> 2296727.5 | I8: =IF(I$5="Actual",i_Historical!I10,H8*(1+i_Inputs!I8)) -> 2526400.2
B9: Food & goods delivery revenue | E9: =IF(E$5="Actual",i_Historical!E11,D9*(1+i_Inputs!E9)) -> 185469 | F9: =IF(F$5="Actual",i_Historical!F11,E9*(1+i_Inputs!F9)) -> 240737 | G9: =IF(G$5="Actual",i_Historical!G11,F9*(1+i_Inputs!G9)) -> 284069.66 | H9: =IF(H$5="Actual",i_Historical!H11,G9*(1+i_Inputs!H9)) -> 329520.81 | I9: =IF(I$5="Actual",i_Historical!I11,H9*(1+i_Inputs!I9)) -> 375653.72
B10: Rental services revenue | E10: =IF(E$5="Actual",i_Historical!E12,D10*(1+i_Inputs!E10)) -> 172678 | F10: =IF(F$5="Actual",i_Historical!F12,E10*(1+i_Inputs!F10)) -> 182685 | G10: =IF(G$5="Actual",i_Historical!G12,F10*(1+i_Inputs!G10)) -> 210087.75 | H10: =IF(H$5="Actual",i_Historical!H12,G10*(1+i_Inputs!H10)) -> 241600.91 | I10: =IF(I$5="Actual",i_Historical!I12,H10*(1+i_Inputs!I10)) -> 270593.02
B11: Total Sales Revenue | E11: =SUM(E8:E10) -> 1992054 | F11: =SUM(F8:F10) -> 2270854 | G11: =SUM(G8:G10) -> 2563281.2 | H11: =SUM(H8:H10) -> 2867849.2 | I11: =SUM(I8:I10) -> 3172646.9
B12: YoY revenue growth rate (%) | E12: =IF(D11=0, 0, E11/D11-1) -> 0 | F12: =IF(E11=0, 0, F11/E11-1) -> 0.13995605 | G12: =IF(F11=0, 0, G11/F11-1) -> 0.12877413 | H12: =IF(G11=0, 0, H11/G11-1) -> 0.11881955 | I12: =IF(H11=0, 0, I11/H11-1) -> 0.10628096
A14: ' | B14: COGS and Opex Breakdown
B16: COGS/ selling expenses | E16: =IF(E$5="Actual",i_Historical!E14,-E$11*i_Inputs!E14) -> -864477 | F16: =IF(F$5="Actual",i_Historical!F14,-F$11*i_Inputs!F14) -> -831240 | G16: =IF(G$5="Actual",i_Historical!G14,-G$11*i_Inputs!G14) -> -909964.84 | H16: =IF(H$5="Actual",i_Historical!H14,-H$11*i_Inputs!H14) -> -1003747.2 | I16: =IF(I$5="Actual",i_Historical!I14,-I$11*i_Inputs!I14) -> -1094563.2
B18: Marketing expenses | E18: =IF(E$5="Actual",i_Historical!E16,-E$11*i_Inputs!E16) -> -795513 | F18: =IF(F$5="Actual",i_Historical!F16,-F$11*i_Inputs!F16) -> -1048370 | G18: =IF(G$5="Actual",i_Historical!G16,-G$11*i_Inputs!G16) -> -1153476.6 | H18: =IF(H$5="Actual",i_Historical!H16,-H$11*i_Inputs!H16) -> -1218835.9 | I18: =IF(I$5="Actual",i_Historical!I16,-I$11*i_Inputs!I16) -> -1269058.8
B19: Research and development expenses | E19: =IF(E$5="Actual",i_Historical!E17,-E$11*i_Inputs!E17) -> -107877 | F19: =IF(F$5="Actual",i_Historical!F17,-F$11*i_Inputs!F17) -> -127580 | G19: =IF(G$5="Actual",i_Historical!G17,-G$11*i_Inputs!G17) -> -128164.06 | H19: =IF(H$5="Actual",i_Historical!H17,-H$11*i_Inputs!H17) -> -143392.46 | I19: =IF(I$5="Actual",i_Historical!I17,-I$11*i_Inputs!I17) -> -158632.35
B20: General and administrative expenses | E20: =IF(E$5="Actual",i_Historical!E18,-E$11*i_Inputs!E18) -> -319933 | F20: =IF(F$5="Actual",i_Historical!F18,-F$11*i_Inputs!F18) -> -253032 | G20: =IF(G$5="Actual",i_Historical!G18,-G$11*i_Inputs!G18) -> -307593.75 | H20: =IF(H$5="Actual",i_Historical!H18,-H$11*i_Inputs!H18) -> -344141.9 | I20: =IF(I$5="Actual",i_Historical!I18,-I$11*i_Inputs!I18) -> -380717.63
B21: Other operating expenses | E21: =IF(E$5="Actual",i_Historical!E19,-E$11*i_Inputs!E19) -> -8913 | F21: =IF(F$5="Actual",i_Historical!F19,-F$11*i_Inputs!F19) -> -13131 | G21: =IF(G$5="Actual",i_Historical!G19,-G$11*i_Inputs!G19) -> -51265.625 | H21: =IF(H$5="Actual",i_Historical!H19,-H$11*i_Inputs!H19) -> -57356.984 | I21: =IF(I$5="Actual",i_Historical!I19,-I$11*i_Inputs!I19) -> -63452.939
B22: Other operating income | E22: =IF(E$5="Actual",i_Historical!E20,E$11*i_Inputs!E20) -> 16924 | F22: =IF(F$5="Actual",i_Historical!F20,F$11*i_Inputs!F20) -> 21953 | G22: =IF(G$5="Actual",i_Historical!G20,G$11*i_Inputs!G20) -> 25632.812 | H22: =IF(H$5="Actual",i_Historical!H20,H$11*i_Inputs!H20) -> 28678.492 | I22: =IF(I$5="Actual",i_Historical!I20,I$11*i_Inputs!I20) -> 31726.469
B23: Total Operating Costs | E23: =SUM(E18:E22) -> -1215312 | F23: =SUM(F18:F22) -> -1420160 | G23: =SUM(G18:G22) -> -1614867.2 | H23: =SUM(H18:H22) -> -1735048.8 | I23: =SUM(I18:I22) -> -1840135.2
B24: % of sales revenue | E24: =-E23/E11 -> 0.61007985 | F24: =-F23/F11 -> 0.62538587 | G24: =-G23/G11 -> 0.63 | H24: =-H23/H11 -> 0.605 | I24: =-I23/I11 -> 0.58
A26: ' | B26: Working Capital Schedule
B28: Trade and other receivables | E28: =IF(E$5="Actual",i_Historical!E31,E11*i_Inputs!E24/365) -> 100732 | F28: =IF(F$5="Actual",i_Historical!F31,F11*i_Inputs!F24/365) -> 127467 | G28: =IF(G$5="Actual",i_Historical!G31,G11*i_Inputs!G24/365) -> 140453.77 | H28: =IF(H$5="Actual",i_Historical!H31,H11*i_Inputs!H24/365) -> 157142.42 | I28: =IF(I$5="Actual",i_Historical!I31,I11*i_Inputs!I24/365) -> 173843.67
B29: Trade and other payables | E29: =IF(E$5="Actual",i_Historical!E38,-c_FS!E16*i_Inputs!E25/365) -> 136657 | F29: =IF(F$5="Actual",i_Historical!F38,-c_FS!F16*i_Inputs!F25/365) -> 188970 | G29: =IF(G$5="Actual",i_Historical!G38,-c_FS!G16*i_Inputs!G25/365) -> 211909.62 | H29: =IF(H$5="Actual",i_Historical!H38,-c_FS!H16*i_Inputs!H25/365) -> 219999.39 | I29: =IF(I$5="Actual",i_Historical!I38,-c_FS!I16*i_Inputs!I25/365) -> 239904.26
B30: Net Working Capital (NWC) | D30: =i_Inputs!$D$26 -> -34555 | E30: =E28-E29 -> -35925 | F30: =F28-F29 -> -61503 | G30: =G28-G29 -> -71455.854 | H30: =H28-H29 -> -62856.968 | I30: =I28-I29 -> -66060.594
B31: Change in net working capital (ΔNWC) | E31: =E30-D30 -> -1370 | F31: =F30-E30 -> -25578 | G31: =G30-F30 -> -9952.854 | H31: =H30-G30 -> 8598.8857 | I31: =I30-H30 -> -3203.6257
A33: ' | B33: Fixed Asset Schedule
B35: Opening fixed assets (PP&E + ROU) | E35: =D39 -> 209987 | F35: =E39 -> 189638 | G35: =F39 -> 180405 | H35: =G39 -> 181283.5 | I35: =H39 -> 181898.45
B36: Add: capital expenditures | E36: =IF(E$5="Actual",-i_Historical!E54,i_Inputs!E28) -> 24860 | F36: =IF(F$5="Actual",-i_Historical!F54,i_Inputs!F28) -> 49348 | G36: =IF(G$5="Actual",-i_Historical!G54,i_Inputs!G28) -> 55000 | H36: =IF(H$5="Actual",-i_Historical!H54,i_Inputs!H28) -> 55000 | I36: =IF(I$5="Actual",-i_Historical!I54,i_Inputs!I28) -> 55000
B37: Less: depreciation & amortization | E37: =IF(E$5="Actual",-i_Historical!E53,-E35*i_Inputs!$D$29) -> -57437 | F37: =IF(F$5="Actual",-i_Historical!F53,-F35*i_Inputs!$D$29) -> -57218 | G37: =IF(G$5="Actual",-i_Historical!G53,-G35*i_Inputs!$D$29) -> -54121.5 | H37: =IF(H$5="Actual",-i_Historical!H53,-H35*i_Inputs!$D$29) -> -54385.05 | I37: =IF(I$5="Actual",-i_Historical!I53,-I35*i_Inputs!$D$29) -> -54569.535
B38: Add: ROU fleet additions / other fixed asset movements | E38: =IF(E$5="Actual",i_Historical!E34-SUM(E35:E37),i_Inputs!E31) -> 12228 | F38: =IF(F$5="Actual",i_Historical!F34-SUM(F35:F37),i_Inputs!F31) -> -1363 | G38: =IF(G$5="Actual",i_Historical!G34-SUM(G35:G37),i_Inputs!G31) -> 0 | H38: =IF(H$5="Actual",i_Historical!H34-SUM(H35:H37),i_Inputs!H31) -> 0 | I38: =IF(I$5="Actual",i_Historical!I34-SUM(I35:I37),i_Inputs!I31) -> 0
B39: Closing fixed assets (PP&E + ROU) | D39: =i_Inputs!D30 -> 209987 | E39: =SUM(E35:E38) -> 189638 | F39: =SUM(F35:F38) -> 180405 | G39: =SUM(G35:G38) -> 181283.5 | H39: =SUM(H35:H38) -> 181898.45 | I39: =SUM(I35:I38) -> 182328.92
A41: ' | B41: Debt & Financing Obligations
B43: Opening debt & convertible bond balance | E43: =D46 -> 139715 | F43: =E46 -> 138498 | G43: =F46 -> 527 | H43: =G46 -> 0 | I43: =H46 -> 0
B44: Add: drawdowns | E44: =IF(E$5="Actual",0,MAX(0,N(i_Inputs!E36))) -> 0 | F44: =IF(F$5="Actual",0,MAX(0,N(i_Inputs!F36))) -> 0 | G44: =IF(G$5="Actual",0,MAX(0,N(i_Inputs!G36))) -> 0 | H44: =IF(H$5="Actual",0,MAX(0,N(i_Inputs!H36))) -> 0 | I44: =IF(I$5="Actual",0,MAX(0,N(i_Inputs!I36))) -> 0
B45: Less: repayments / derecognition via equity conversion | E45: =IF(E$5="Actual",i_Historical!E39-SUM(E43:E44), MIN(0,N(i_Inputs!E36))) -> -1217 | F45: =IF(F$5="Actual",i_Historical!F39-SUM(F43:F44), MIN(0,N(i_Inputs!F36))) -> -137971 | G45: =IF(G$5="Actual",i_Historical!G39-SUM(G43:G44), MIN(0,N(i_Inputs!G36))) -> -527 | H45: =IF(H$5="Actual",i_Historical!H39-SUM(H43:H44), MIN(0,N(i_Inputs!H36))) -> 0 | I45: =IF(I$5="Actual",i_Historical!I39-SUM(I43:I44), MIN(0,N(i_Inputs!I36))) -> 0
B46: Closing debt balance | D46: =i_Inputs!D37 -> 139715 | E46: =SUM(E43:E45) -> 138498 | F46: =SUM(F43:F45) -> 527 | G46: =SUM(G43:G45) -> 0 | H46: =SUM(H43:H45) -> 0 | I46: =SUM(I43:I45) -> 0
B48: Opening lease liabilities balance | E48: =D52 -> 96820 | F48: =E52 -> 98876 | G48: =F52 -> 107037 | H48: =G52 -> 96764.766 | I48: =H52 -> 85729.304
B49: Add: ROU fleet additions / other lease movements | E49: =E38 -> 12228 | F49: =F38 -> -1363 | G49: =G38 -> 0 | H49: =H38 -> 0 | I49: =I38 -> 0
B50: Add: lease interest accretion | E50: =-E55 -> 7193.726 | F50: =-F55 -> 7346.4868 | G50: =-G55 -> 7952.8491 | H50: =-H55 -> 7189.6221 | I50: =-I55 -> 6369.6873
B51: Less: lease cash payments | E51: =IF(E$5="Actual",i_Historical!E40-SUM(E48:E50),-i_Inputs!E41) -> -17365.726 | F51: =IF(F$5="Actual",i_Historical!F40-SUM(F48:F50),-i_Inputs!F41) -> 2177.5132 | G51: =IF(G$5="Actual",i_Historical!G40-SUM(G48:G50),-i_Inputs!G41) -> -18225.083 | H51: =IF(H$5="Actual",i_Historical!H40-SUM(H48:H50),-i_Inputs!H41) -> -18225.083 | I51: =IF(I$5="Actual",i_Historical!I40-SUM(I48:I50),-i_Inputs!I41) -> -18225.083
B52: Closing lease liabilities balance | D52: =i_Inputs!D40 -> 96820 | E52: =SUM(E48:E51) -> 98876 | F52: =SUM(F48:F51) -> 107037 | G52: =SUM(G48:G51) -> 96764.766 | H52: =SUM(H48:H51) -> 85729.304 | I52: =SUM(I48:I51) -> 73873.908
...

Sheet Input>>

Sheet i_Inputs
A1: =Contents!$A1 -> Bolt Technology OÜ - Draft Valuation Model
A2: =Contents!$A2 -> Source: Bolt Technology OÜ Consolidated Annual Report 2025 (AS PricewaterhouseCoopers audit)
C4: Unit | E4: =i_Historical!E4 -> 2024A | F4: =i_Historical!F4 -> 2025A | G4: =i_Historical!G4 -> 2026E | H4: =i_Historical!H4 -> 2027E | I4: =i_Historical!I4 -> 2028E | J4: Benchmark / Notes
E5: =i_Historical!E5 -> Actual | F5: =i_Historical!F5 -> Actual | G5: =i_Historical!G5 -> Estimate | H5: =i_Historical!H5 -> Estimate | I5: =i_Historical!I5 -> Estimate
A6: ' | B6: Grown Drivers
B8: Ride-hailing revenue | C8: % | G8: 0.12 | H8: 0.11 | I8: 0.1 | J8: Mature platform equilibrium; AV pilot additions in EU
B9: Food & delivery | C9: % | G9: 0.18 | H9: 0.16 | I9: 0.14 | J9: Bolt Plus subscriber adoption (already >20% GMV in core mkts)
B10: Rental & drive revenue | C10: % | G10: 0.15 | H10: 0.15 | I10: 0.12 | J10: Micromobility tender wins (UK, London e-bikes, Brussels)
A12: ' | B12: COGS & Opex Assumptions (% of Revenue)
B14: COGS / selling expenses | C14: % | G14: 0.355 | H14: 0.35 | I14: 0.345 | J14: Down from 36.6% in 2025 due to transport cost optimization
B16: Marketing spend | C16: % | G16: 0.45 | H16: 0.425 | I16: 0.4 | J16: Current is 46.2%; Opening post-expansion normalization
B17: R&D spend | C17: % | G17: 0.05 | H17: 0.05 | I17: 0.05 | J17: Sustained tech talent density & AV integration with Pony.ai
B18: G&A | C18: % | G18: 0.12 | H18: 0.12 | I18: 0.12 | J18: Corporate overhead fixed cost operating leverage
B19: Other operating expenses | C19: % | G19: 0.02 | H19: 0.02 | I19: 0.02 | J19: Receivable discounts & write-offs
B20: Other operating income | C20: % | G20: 0.01 | H20: 0.01 | I20: 0.01 | J20: Consistent with historical 2025 other income
A22: ' | B22: Working Capital & Capex
B24: Trade receivables | C24: days | G24: 20 | H24: 20 | I24: 20 | J24: Consistent with historical 2025 net receivables (~€127M)
B25: Trade payables | C25: days | G25: 85 | H25: 80 | I25: 80 | J25: Consistent with historical payment terms with fleet/suppliers
B26: Closing working capital balance as of 31.12.2023 | C26: EUR '000 | D26: -34555 | J26: Bolt Technology OÜ Consolidated Annual Report 2024
B28: PP&E capex | C28: EUR '000 | G28: 55000 | H28: 55000 | I28: 55000 | J28: (€55.0M/yr) to fund recurring micromobility fleet renewals (Note 8 notes an existing €15.7M purchase commitment)
B29: D&A rate p.a (blended) | C29: % | D29: 0.3 | J29: Reflects 3-8 yr scooter life and 2-3 yr vehicle lease life
B30: Closing PPE and ROU balance as of 31.12.2023 | C30: EUR '000 | D30: 209987 | J30: Bolt Technology OÜ Consolidated Annual Report 2024
B31: ROU fleet additions / other fixed asset movements | C31: EUR '000 | J31: Historical periods solve for other fixed-asset movements so the roll-forward ties to audited closing PP&E + ROU. Forecast periods use the explicit ROU-additions control input.
A33: ' | B33: Debt & Financing Obligations
B35: Cost of debt p.a | C35: % | D35: 0.045 | J35: 3-Month EURIBOR (~2.65%) + 175–250 bps margin
B36: Net debt drawdown / (repayment) | C36: EUR '000 | G36: -527 | J36: Placeholder (enter positive value for debt drawdown / negative for repayment)
B37: Closing debt balance as of 31.12.2023 | C37: EUR '000 | D37: 139715 | J37: Bolt Technology OÜ Consolidated Annual Report 2024
B39: Effective incremental borrowing rate p.a | C39: % | D39: 0.0743 | J39: Bolt Technology OÜ Consolidated Annual Report 2025
B40: Closing lease liabilities as of 31.12.2023 | C40: EUR '000 | D40: 96820 | J40: Bolt Technology OÜ Consolidated Annual Report 2024
B41: Lease cash payments | C41: EUR '000 | G41: =PMT($D$39,$D$42,-c_FS!$F$52) -> 18225.083 | H41: =PMT($D$39,$D$42,-c_FS!$F$52) -> 18225.083 | I41: =PMT($D$39,$D$42,-c_FS!$F$52) -> 18225.083 | J41: Periodic fixed payment (PMT)
B42: Payment period | C42: Years | D42: 8
A44: ' | B44: Other Assumptions
B46: Interest yield on cash p.a | C46: % | D46: 0.02 | J46: Bolt had over €206M in money market funds (MMFs) and €134M in tier-1 bank accounts (rated Aa3/Baa1 by Moody’s) (Note 5)
B47: Closing cash balance as of 31.12.2023 | C47: EUR '000 | D47: 325013 | J47: Bolt Technology OÜ Consolidated Annual Report 2024
B49: Effective corporate tax rate | C49: % | D49: 0.22
B50: Other non-recurring instruments | C50: EUR '000 | G50: 0 | H50: 0 | I50: 0
A52: ' | B52: Valuation and IPO Capital Market Assumptions
B54: Weighted Average Cost of Capital (WACC) | C54: % | D54: 0.105 | J54: Risk-free 2.5% + Beta 1.30 + Equity Risk Premium 6.0%
B55: Terminal Growth Rate (DCF) | C55: % | D55: 0.04 | J55: Long-term GDP + growth for urban shared mobility
B56: Target EV / Sales Multiple (Public Comps) | C56: x | D56: 2.5 | J56: Uber trades at ~3.0x; Grab trades at ~2.7x forward revenue
...

Sheet i_Historical
A1: =Contents!$A1 -> Bolt Technology OÜ - Draft Valuation Model
A2: =Contents!$A2 -> Source: Bolt Technology OÜ Consolidated Annual Report 2025 (AS PricewaterhouseCoopers audit)
C4: Unit | E4: 2024A | F4: 2025A | G4: 2026E | H4: 2027E | I4: 2028E | K4: YoY Change (€) | L4: YoY Change (%) | M4: Source Note
E5: =IF(RIGHT(E4)="A","Actual","Estimate") -> Actual | F5: =IF(RIGHT(F4)="A","Actual","Estimate") -> Actual | G5: =IF(RIGHT(G4)="A","Actual","Estimate") -> Estimate | H5: =IF(RIGHT(H4)="A","Actual","Estimate") -> Estimate | I5: =IF(RIGHT(I4)="A","Actual","Estimate") -> Estimate
A6: ' | B6: Historical Consolidated Statement of Financial Position (click to follow source)
B8: Income Statement
B10: Ride-hailing revenue | C10: EUR '000 | E10: 1633907 | F10: 1847432 | K10: =F10-E10 -> 213525 | L10: =IF(E10=0,"N/a",K10/ABS(E10)) -> 0.13068369 | M10: Note 17
B11: Food & goods delivery revenue | C11: EUR '000 | E11: 185469 | F11: 240737 | K11: =F11-E11 -> 55268 | L11: =IF(E11=0,"N/a",K11/ABS(E11)) -> 0.2979905 | M11: Note 17
B12: Rental services revenue (Micromobility & Drive) | C12: EUR '000 | E12: 172678 | F12: 182685 | K12: =F12-E12 -> 10007 | L12: =IF(E12=0,"N/a",K12/ABS(E12)) -> 0.057951795 | M12: Note 17
B13: Total Sales Revenue | C13: EUR '000 | E13: 1992054 | F13: 2270854 | K13: =F13-E13 -> 278800 | L13: =IF(E13=0,"N/a",K13/ABS(E13)) -> 0.13995605 | M13: Note 17
B14: COGS/ selling expenses | C14: EUR '000 | E14: -864477 | F14: -831240 | K14: =F14-E14 -> 33237 | L14: =IF(E14=0,"N/a",K14/ABS(E14)) -> 0.038447524 | M14: Note 20
B15: Gross Profit | C15: EUR '000 | E15: 1127577 | F15: 1439614 | K15: =F15-E15 -> 312037 | L15: =IF(E15=0,"N/a",K15/ABS(E15)) -> 0.27673232 | M15: P&L
B16: Marketing expenses | C16: EUR '000 | E16: -795513 | F16: -1048370 | K16: =F16-E16 -> -252857 | L16: =IF(E16=0,"N/a",K16/ABS(E16)) -> -0.31785401 | M16: Note 22
B17: Research and development expenses | C17: EUR '000 | E17: -107877 | F17: -127580 | K17: =F17-E17 -> -19703 | L17: =IF(E17=0,"N/a",K17/ABS(E17)) -> -0.1826432 | M17: Note 21
B18: General and administrative expenses | C18: EUR '000 | E18: -319933 | F18: -253032 | K18: =F18-E18 -> 66901 | L18: =IF(E18=0,"N/a",K18/ABS(E18)) -> 0.20910941 | M18: Note 23
B19: Other operating expenses | C19: EUR '000 | E19: -8913 | F19: -13131 | K19: =F19-E19 -> -4218 | L19: =IF(E19=0,"N/a",K19/ABS(E19)) -> -0.47324133 | M19: Note 19
B20: Other operating income | C20: EUR '000 | E20: 16924 | F20: 21953 | K20: =F20-E20 -> 5029 | L20: =IF(E20=0,"N/a",K20/ABS(E20)) -> 0.29715197 | M20: Note 18
B21: Operating Profit / (Loss) (EBIT) | C21: EUR '000 | E21: -87735 | F21: 19454 | K21: =F21-E21 -> 107189 | L21: =IF(E21=0,"N/a",K21/ABS(E21)) -> 1.2217359 | M21: P&L
... B26: Net Profit / (Loss) for the period | C26: EUR '000 | E26: -102594 | F26: 920 | K26: =F26-E26 -> 103514 | L26: =IF(E26=0,"N/a",K26/ABS(E26)) -> 1.0089674 | M26: P&L
B28: Balance Sheet & Capitalization Actuals
B30: Cash and cash equivalents | C30: EUR '000 | E30: 342247 | F30: 357038 | K30: =F30-E30 -> 14791 | L30: =IF(E30=0,"N/a",K30/ABS(E30)) -> 0.043217325 | M30: Note 5
B31: Trade and other receivables and prepayments | C31: EUR '000 | E31: 100732 | F31: 127467 | K31: =F31-E31 -> 26735 | L31: =IF(E31=0,"N/a",K31/ABS(E31)) -> 0.26540722 | M31: Note 6
B32: Other current assets | C32: EUR '000 | E32: =E33-SUM(E30:E31) -> 14105 | F32: =F33-SUM(F30:F31) -> 16675 | G32: =G33-SUM(G30:G31) -> 0 | H32: =H33-SUM(H30:H31) -> 0 | I32: =I33-SUM(I30:I31) -> 0 | K32: =F32-E32 -> 2570 | L32: =IF(E32=0,"N/a",K32/ABS(E32)) -> 0.18220489
B33: Total current assets | C33: EUR '000 | E33: 457084 | F33: 501180 | K33: =F33-E33 -> 44096 | L33: =IF(E33=0,"N/a",K33/ABS(E33)) -> 0.096472421 | M33: Balance Sheet
B34: Fixed asset (PPE + ROU) | C34: EUR '000 | E34: 189638 | F34: 180405 | K34: =F34-E34 -> -9233 | L34: =IF(E34=0,"N/a",K34/ABS(E34)) -> -0.048687499 | M34: Note 8 & 9
B35: Other non-current assets | C35: EUR '000 | E35: =E36-E34 -> 134298 | F35: =F36-F34 -> 150910 | G35: =G36-G34 -> 0 | H35: =H36-H34 -> 0 | I35: =I36-I34 -> 0 | K35: =F35-E35 -> 16612 | L35: =IF(E35=0,"N/a",K35/ABS(E35)) -> 0.12369507
B36: Total non-current assets | C36: EUR '000 | E36: 323936 | F36: 331315 | K36: =F36-E36 -> 7379 | L36: =IF(E36=0,"N/a",K36/ABS(E36)) -> 0.022779191 | M36: Balance Sheet
B37: Total Assets | C37: EUR '000 | E37: 781020 | F37: 832495 | K37: =F37-E37 -> 51475 | L37: =IF(E37=0,"N/a",K37/ABS(E37)) -> 0.065907403 | M37: Balance Sheet
B38: Trade and other payables | C38: EUR '000 | E38: 136657 | F38: 188970 | K38: =F38-E38 -> 52313 | L38: =IF(E38=0,"N/a",K38/ABS(E38)) -> 0.38280513 | M38: Note 11
B39: Funded debt / convertible bonds | C39: EUR '000 | E39: 138498 | F39: 527 | K39: =F39-E39 -> -137971 | L39: =IF(E39=0,"N/a",K39/ABS(E39)) -> -0.99619489 | M39: Note 12
B40: Lease obligations (current + non-current) | C40: EUR '000 | E40: 98876 | F40: 107037 | K40: =F40-E40 -> 8161 | L40: =IF(E40=0,"N/a",K40/ABS(E40)) -> 0.082537724 | M40: Note 14
B41: Balance sheet provisions (legal + tax) | C41: EUR '000 | E41: 185296 | F41: 155073 | K41: =F41-E41 -> -30223 | L41: =IF(E41=0,"N/a",K41/ABS(E41)) -> -0.1631066 | M41: Note 15
B42: Other liabilities | C42: EUR '000 | E42: =E43-SUM(E38:E41) -> 20454 | F42: =F43-SUM(F38:F41) -> 20904 | G42: =G43-SUM(G38:G41) -> 0 | H42: =H43-SUM(H38:H41) -> 0 | I42: =I43-SUM(I38:I41) -> 0 | K42: =F42-E42 -> 450 | L42: =IF(E42=0,"N/a",K42/ABS(E42)) -> 0.022000587
B43: Total Liabilities | C43: EUR '000 | E43: 579781 | F43: 472511 | K43: =F43-E43 -> -107270 | L43: =IF(E43=0,"N/a",K43/ABS(E43)) -> -0.18501814 | M43: Balance Sheet
B44: Total Equity | C44: EUR '000 | E44: 201239 | F44: 359984 | K44: =F44-E44 -> 158745 | L44: =IF(E44=0,"N/a",K44/ABS(E44)) -> 0.78883815 | M44: Balance Sheet
A45: =IF(SUM(E45:I45)<>0,"Error","OK") -> OK | B45: BS Check | C45: Check | E45: =E37-(E43+E44) -> 0 | F45: =F37-(F43+F44) -> 0 | G45: =G37-(G43+G44) -> 0 | H45: =H37-(H43+H44) -> 0 | I45: =I37-(I43+I44) -> 0
B47: Shares outstanding (registered) | C47: Thousands | E47: 28823 | F47: 28823 | K47: =F47-E47 -> 0 | L47: =IF(E47=0,"N/a",K47/ABS(E47)) -> 0 | M47: Note 16
B48: Unregistered shares from convertible bond conversion | C48: Thousands | E48: 0 | F48: 2400 | K48: =F48-E48 -> 2400 | L48: =IF(E48=0,"N/a",K48/ABS(E48)) -> N/a | M48: Note 16
B49: Total Share Count (Diluted) | C49: Thousands | E49: 28823 | F49: 31223 | K49: =F49-E49 -> 2400 | L49: =IF(E49=0,"N/a",K49/ABS(E49)) -> 0.083266836 | M49: Note 16
B51: Cash Flow Highlights
...
