Workbook

Sheet Contents
A1: Bolt Technology OÜ|Pre-IPO Equity Valuation Model
A2: Source: Bolt Technology OÜ Consolidated Annual Report 2024-25 (AS PricewaterhouseCoopers audit)
A4: ' | B4: Contents
B25: Disclaimer: This model is a draft prepared for illustrative and analytical purposes only. Forward-looking figures (2026E-2028E), valuation multiples, and implied share prices are based on assumptions and estimates that are inherently uncertain and may differ materially from actual results. Historical figures are extracted from the Bolt Technology OÜ Consolidated Annual Reports 2024-25 and have not been independently verified. Nothing in this model constitutes investment, financial, legal or tax advice, an offer or solicitation to buy or sell any security, or a recommendation regarding any IPO. No output should be relied upon for any investment decision. The author accepts no liability for any loss arising from use of, or reliance on, this model.
B26: Confidentiality: Any unauthorized reproduction, distribution, dissemination, or disclosure of these materials to third parties without prior written consent is strictly prohibited.
A28: ' | B28: End of Worksheet

Sheet How To
A1: =Contents!$A1 -> Bolt Technology OÜ|Pre-IPO Equity Valuation Model
A2: =Contents!$A2 -> Source: Bolt Technology OÜ Consolidated Annual Report 2024-25 (AS PricewaterhouseCoopers audit)
A5: ' | B5: Scope
B7: This financial model delivers a top-down operational forecasting and corporate valuation engine designed to evaluate high-volume platform unit economics, Free Cash Flow to Firm (FCFF), and equity valuation for Bolt's pre-IPO assessment.
B9: Key Features:
B10: Calibrated using audited 2024–2025 historical actuals to drive a multi-year projection period spanning 2026–2028 estimates.
B11: Examines downside resilience and operating leverage by stress-testing EBITDA and cash conversion against five configurable operational scenarios.
B12: Produces a ground-up DCF (using mid-year discounting) paired with market trading multiple benchmarks to determine implied Enterprise Value, equity dilution parameters, and target share value.
A14: ' | B14: Model Key
B16: i_ | C16: Inputs & Assumptions | D16: Hardcoded data, historical figures, and model assumptions
B17: c_ | C17: Calculations | D17: Dynamic formulas and cross-sheet links
B18: o_ | C18: Valuation Outputs | D18: Blended pre-money enterprise and equity valuations & IPO pricing analysis
B19: >> | C19: Section Dividers | D19: Navigation tabs separating Input, Calcs and Output sections
A21: ' | B21: Model Roll-Forward and User Manual
B23: Note: To preserve formula architecture and audit integrity, all calculation and output sheets are password-protected. Users should modify assumptions exclusively within sheets located under the INPUT >> section divider.
B25: Step 1: Set Model Timeline
B26: Define the model start date and forecast start date on the i_Historical tab. Setting these dates dynamically configures the timeline across the entire model.
B28: Step 2: Enter Historical Data
B29: Populate actual historical figures in i_Historical. Because the model uses a top-down architecture, historical baselines are required to drive the forecast calculations.
B31: Step 3: Configure Forecast Drivers
B32: Navigate to the i_Inputs tab and input forward-looking assumptions across Columns D:J.
B34: Step 4 (Optional): Adjust Scenarios & Sensitivities
B35: Modify scenario toggles and sensitivity deltas (+/-%) within the i_Scenario_Manager tab. The workbook defaults to the Base Case with standard baseline commercial assumptions.
A37: ' | B37: End of Worksheet

Sheet Output>>

Sheet o_Dashboard
A1: =Contents!$A1 -> Bolt Technology OÜ|Pre-IPO Equity Valuation Model
A2: =Contents!$A2 -> Source: Bolt Technology OÜ Consolidated Annual Report 2024-25 (AS PricewaterhouseCoopers audit)
F3: =i_Scenario_Manager!B6 -> Selected Case | G3: =i_Scenario_Manager!C6 -> 3
B5: KEY VALUATION OUTPUTS
B7: =o_Valuation!B81 -> Target Price post IPO Discount
B8: =o_Valuation!D81 -> 143.70015
B10: =o_Valuation!B75 -> Blended Target Pre-Money Equity Value
B11: =o_Valuation!D75 -> 4824462
B13: FINANCIAL SUMMARY
B15: Metric | C15: =o_FS!E4 -> 2024A | D15: =o_FS!F4 -> 2025A | E15: =o_FS!G4 -> 2026E | F15: =o_FS!H4 -> 2027E | G15: =o_FS!I4 -> 2028E
C16: =o_FS!E5 -> Actual | D16: =o_FS!F5 -> Actual | E16: =o_FS!G5 -> Estimate | F16: =o_FS!H5 -> Estimate | G16: =o_FS!I5 -> Estimate
B17: =o_FS!B8 -> Sales revenue | C17: =o_FS!E8 -> 1992054 | D17: =o_FS!F8 -> 2270854 | E17: =o_FS!G8 -> 2563281.2 | F17: =o_FS!H8 -> 2867849.2 | G17: =o_FS!I8 -> 3172646.9
B18: =c_FS!B12 -> YoY revenue growth rate (%) | C18: =c_FS!E12 -> 0 | D18: =c_FS!F12 -> 0.13995605 | E18: =c_FS!G12 -> 0.12877413 | F18: =c_FS!H12 -> 0.11881955 | G18: =c_FS!I12 -> 0.10628096
B19: =o_FS!B11 -> Gross Margin % | C19: =o_FS!E11 -> 0.56603737 | D19: =o_FS!F11 -> 0.63395269 | E19: =o_FS!G11 -> 0.645 | F19: =o_FS!H11 -> 0.65 | G19: =o_FS!I11 -> 0.655
B20: =o_FS!B20 -> EBITDA | C20: =o_FS!E20 -> -30298 | D20: =o_FS!F20 -> 76672 | E20: =o_FS!G20 -> 92570.719 | F20: =o_FS!H20 -> 183438.26 | G20: =o_FS!I20 -> 292518.06
B21: =o_FS!B21 -> EBITDA Margin % | C21: =o_FS!E21 -> -0.015209427 | D21: =o_FS!F21 -> 0.033763509 | E21: =o_FS!G21 -> 0.036114148 | F21: =o_FS!H21 -> 0.063963706 | G21: =o_FS!I21 -> 0.092200002
B22: =o_FS!B17 -> Operating Profit / (Loss) (EBIT) | C22: =o_FS!E17 -> -87735 | D22: =o_FS!F17 -> 19454 | E22: =o_FS!G17 -> 38449.219 | F22: =o_FS!H17 -> 129053.21 | G22: =o_FS!I17 -> 237948.52
B23: =o_FS!B26 -> Net Profit / (Loss) for the Period | C23: =o_FS!E26 -> -102594 | D23: =o_FS!F26 -> 920 | E23: =o_FS!G26 -> 29347.712 | F23: =o_FS!H26 -> 101054.31 | G23: =o_FS!I26 -> 187892.76
B24: =o_FS!B35 -> Free Cash Flow to Firm (FCFF) | C24: =o_FS!E35 -> -34486.3 | D24: =o_FS!F35 -> 48622.12 | E24: =o_FS!G35 -> 39064.745 | F24: =o_FS!H35 -> 91447.671 | G24: =o_FS!I35 -> 188373.01
B25: =o_FS!B39 -> Closing cash & cash equivalents | C25: =o_FS!E39 -> 342247 | D25: =o_FS!F39 -> 357038 | E25: =o_FS!G39 -> 384660.83 | F25: =o_FS!H39 -> 465465.84 | G25: =o_FS!I39 -> 644276.37
B26: =o_FS!B42 -> Net Cash / (Net Debt) Position | C26: =o_FS!E42 -> 104873 | D26: =o_FS!F42 -> 249474 | E26: =o_FS!G42 -> 287896.07 | F26: =o_FS!H42 -> 379736.54 | G26: =o_FS!I42 -> 570402.46
B28: ASSUMPTIONS
B29: =o_Valuation!B30 -> Weighted Average Cost of Capital (WACC) - sensitized | C29: =o_Valuation!D30 -> 0.1020185
B30: =o_Valuation!B31 -> Terminal Growth Rate (g) - sensitized | C30: =o_Valuation!D31 -> 0.04
B31: =i_Inputs!B58 -> Target EV / Sales Multiple | C31: =i_Inputs!D58 -> 2.5
B32: =i_Inputs!B59 -> Target EV / EBITDA Multiple | C32: =i_Inputs!D59 -> 20
B33: =i_Inputs!B49 -> Effective corporate tax rate | C33: =i_Inputs!D49 -> 0.22
B34: =i_Inputs!B62 -> IPO Underwriter Discount / Spread | C34: =i_Inputs!D62 -> 0.07
B35: =o_Valuation!B77 -> Target Primary Capital Raised at IPO | C35: =o_Valuation!D77 -> 500000
B37: CAPITAL STRUCTURE 2025A
B38: =o_Valuation!B52 -> Diluted Shares Outstanding | C38: =o_Valuation!D52 -> 31223
B39: Closing cash | C39: =o_FS!F39 -> 357038
B40: Funded debt | C40: =o_FS!F40 -> -527
B41: Lease liabilities | C41: =o_FS!F41 -> -107037
B42: Undrawn Syndicated Credit Line | C42: =i_Historical!F58 -> 220000
B64: End of Worksheet

Sheet o_Valuation
A1: =Contents!$A1 -> Bolt Technology OÜ|Pre-IPO Equity Valuation Model
A2: =Contents!$A2 -> Source: Bolt Technology OÜ Consolidated Annual Report 2024-25 (AS PricewaterhouseCoopers audit)
B5: CAPM & WACC Build-up
B7: Risk-free rate (Rf) | C7: % | D7: =i_Inputs!$D$73 -> 0.025
B8: Unlevered (asset) beta | C8: x | D8: =i_Inputs!$D$76 -> 1.1
B9: Target debt weight D / (D + E) | C9: % | D9: =i_Inputs!$D$80 -> 0.15
B10: Target equity weight E / (D + E) | C10: % | D10: =i_Inputs!$D$81 -> 0.85
B11: Target debt / equity ratio (D / E) | C11: x | D11: =D9/D10 -> 0.17647059
B12: Marginal tax rate (t) | C12: % | D12: =i_Inputs!$D$79 -> 0.22
B14: Relevered equity beta = Bu x (1 + (1 - t) x D/E) | C14: x | D14: =D8*(1+(1-D12)*D11) -> 1.2514118
B15: Equity risk premium (ERP) | C15: % | D15: =i_Inputs!$D$74 -> 0.055
B16: Country risk premium (CRP) | C16: % | D16: =i_Inputs!$D$75 -> 0.01
B17: Size / company-specific premium | C17: % | D17: =i_Inputs!$D$77 -> 0.01
B18: Cost of Equity (CAPM) = Rf + BL x ERP + CRP + premium | C18: % | D18: =D7+D14*D15+D16+D17 -> 0.11382765
B20: Pre-tax cost of debt (Kd) | C20: % | D20: =i_Inputs!$D$78 -> 0.045
B21: After-tax cost of debt = Kd x (1 - t) | C21: % | D21: =D20*(1-D12) -> 0.0351
B22: WACC (CAPM build-up) = E/V x Ke + D/V x Kd x (1 - t) | C22: % | D22: =D10*D18+D9*D21 -> 0.1020185
B24: Manual WACC override (i_Inputs) | C24: % | D24: =i_Inputs!$D$54 -> 0.105
B25: WACC selection switch (1 = build-up, 0 = manual) | C25: Flag | D25: =i_Inputs!$D$55 -> 1
B26: Selected WACC for DCF | C26: % | D26: =IF(D25=1,D22,D24) -> 0.1020185
B28: DCF Valuation
B30: Weighted Average Cost of Capital (WACC) - sensitized | C30: % | D30: =$D$26*(1+i_Scenario_Manager!$D$26) -> 0.1020185
B31: Terminal Growth Rate (g) - sensitized | C31: % | D31: =i_Inputs!$D$57*(1+i_Scenario_Manager!$D$27) -> 0.04
B32: Mid-year Discounting Convention (period offset) | C32: Years | D32: =i_Inputs!$D$68 -> 0.5
B34: Discounted Cashflow | E34: =o_FS!E4 -> 2024A | F34: =o_FS!F4 -> 2025A | G34: =o_FS!G4 -> 2026E | H34: =o_FS!H4 -> 2027E | I34: =o_FS!I4 -> 2028E
B35: Forecast period flag | C35: Flag | E35: =IF(RIGHT(E$34,1)="E",1,0) -> 0 | F35: =IF(RIGHT(F$34,1)="E",1,0) -> 0 | G35: =IF(RIGHT(G$34,1)="E",1,0) -> 1 | H35: =IF(RIGHT(H$34,1)="E",1,0) -> 1 | I35: =IF(RIGHT(I$34,1)="E",1,0) -> 1
B36: Discount period (t) | C36: Years | E36: =IF(E35=1,SUM($E35:E35)-$D$32,0) -> 0 | F36: =IF(F35=1,SUM($E35:F35)-$D$32,0) -> 0 | G36: =IF(G35=1,SUM($E35:G35)-$D$32,0) -> 0.5 | H36: =IF(H35=1,SUM($E35:H35)-$D$32,0) -> 1.5 | I36: =IF(I35=1,SUM($E35:I35)-$D$32,0) -> 2.5
B37: Terminal year flag | C37: Flag | E37: =IF(AND(E35=1,E36=MAX($E$36:$I$36)),1,0) -> 0 | F37: =IF(AND(F35=1,F36=MAX($E$36:$I$36)),1,0) -> 0 | G37: =IF(AND(G35=1,G36=MAX($E$36:$I$36)),1,0) -> 0 | H37: =IF(AND(H35=1,H36=MAX($E$36:$I$36)),1,0) -> 0 | I37: =IF(AND(I35=1,I36=MAX($E$36:$I$36)),1,0) -> 1
B39: Unlevered FCF | C39: EUR '000 | E39: =o_FS!E35 -> -34486.3 | F39: =o_FS!F35 -> 48622.12 | G39: =o_FS!G35 -> 39064.745 | H39: =o_FS!H35 -> 91447.671 | I39: =o_FS!I35 -> 188373.01
B40: Discount factor | C40: x | E40: =IF(E35=1,1/(1+$D$30)^E36,0) -> 0 | F40: =IF(F35=1,1/(1+$D$30)^F36,0) -> 0 | G40: =IF(G35=1,1/(1+$D$30)^G36,0) -> 0.95258899 | H40: =IF(H35=1,1/(1+$D$30)^H36,0) -> 0.86440381 | I40: =IF(I35=1,1/(1+$D$30)^I36,0) -> 0.7843823
B41: Discounted Unlevered FCF | C41: EUR '000 | E41: =E39*E40 -> 0 | F41: =F39*F40 -> 0 | G41: =G39*G40 -> 37212.646 | H41: =H39*H40 -> 79047.715 | I41: =I39*I40 -> 147756.45
B43: PV of Unlevered FCF | C43: EUR '000 | D43: =SUM(E41:I41) -> 264016.81
B44: Terminal Year Unlevered FCF | C44: EUR '000 | D44: =SUMPRODUCT(E37:I37,E39:I39) -> 188373.01
B45: Terminal Value (Gordon Growth) | C45: EUR '000 | D45: =D44*(1+D31)/(D30-D31) -> 3158862.7
B46: Present Value of Terminal Value | C46: EUR '000 | D46: =D45*SUMPRODUCT(E37:I37,E40:I40) -> 2477756
B47: Enterprise Value (DCF Method) | C47: EUR '000 | D47: =D43+D46 -> 2741772.8
B48: Add: 2025A Cash and Cash Equivalents | C48: EUR '000 | D48: =i_Historical!F32 -> 357038
B49: Less: 2025A Funded Loan Debt | C49: EUR '000 | D49: =-i_Historical!F41 -> -527
B50: Less: 2025A Lease Obligations | C50: EUR '000 | D50: =-i_Historical!F42 -> -107037
B51: Implied Equity Value (DCF Method) | C51: EUR '000 | D51: =D47+D48+D49+D50 -> 2991246.8
...

Sheet o_FS
A1: =Contents!$A1 -> Bolt Technology OÜ|Pre-IPO Equity Valuation Model
A2: =Contents!$A2 -> Source: Bolt Technology OÜ Consolidated Annual Report 2024-25 (AS PricewaterhouseCoopers audit)
B4: (EUR '000 unless stated) | E4: =c_FS!E4 -> 2024A | F4: =c_FS!F4 -> 2025A | G4: =c_FS!G4 -> 2026E | H4: =c_FS!H4 -> 2027E | I4: =c_FS!I4 -> 2028E
E5: =c_FS!E5 -> Actual | F5: =c_FS!F5 -> Actual | G5: =c_FS!G5 -> Estimate | H5: =c_FS!H5 -> Estimate | I5: =c_FS!I5 -> Estimate
B6: Consolidated Income Statement
B8: Sales revenue | E8: =c_FS!E11 -> 1992054 | F8: =c_FS!F11 -> 2270854 | G8: =c_FS!G11 -> 2563281.2 | H8: =c_FS!H11 -> 2867849.2 | I8: =c_FS!I11 -> 3172646.9
B9: COGS/ selling expenses | E9: =c_FS!E16 -> -864477 | F9: =c_FS!F16 -> -831240 | G9: =c_FS!G16 -> -909964.84 | H9: =c_FS!H16 -> -1003747.2 | I9: =c_FS!I16 -> -1094563.2
B10: Gross Profit | E10: =SUM(E8:E9) -> 1127577 | F10: =SUM(F8:F9) -> 1439614 | G10: =SUM(G8:G9) -> 1653316.4 | H10: =SUM(H8:H9) -> 1864102 | I10: =SUM(I8:I9) -> 2078083.8
B11: Gross Margin % | E11: =E10/E8 -> 0.56603737 | F11: =F10/F8 -> 0.63395269 | G11: =G10/G8 -> 0.645 | H11: =H10/H8 -> 0.65 | I11: =I10/I8 -> 0.655
B12: Marketing expenses | E12: =c_FS!E18 -> -795513 | F12: =c_FS!F18 -> -1048370 | G12: =c_FS!G18 -> -1153476.6 | H12: =c_FS!H18 -> -1218835.9 | I12: =c_FS!I18 -> -1269058.8
B13: Research and development expenses | E13: =c_FS!E19 -> -107877 | F13: =c_FS!F19 -> -127580 | G13: =c_FS!G19 -> -128164.06 | H13: =c_FS!H19 -> -143392.46 | I13: =c_FS!I19 -> -158632.35
B14: General and administrative expenses | E14: =c_FS!E20 -> -319933 | F14: =c_FS!F20 -> -253032 | G14: =c_FS!G20 -> -307593.75 | H14: =c_FS!H20 -> -344141.9 | I14: =c_FS!I20 -> -380717.63
B15: Other operating expenses | E15: =c_FS!E21 -> -8913 | F15: =c_FS!F21 -> -13131 | G15: =c_FS!G21 -> -51265.625 | H15: =c_FS!H21 -> -57356.984 | I15: =c_FS!I21 -> -63452.939
B16: Other operating income | E16: =c_FS!E22 -> 16924 | F16: =c_FS!F22 -> 21953 | G16: =c_FS!G22 -> 25632.812 | H16: =c_FS!H22 -> 28678.492 | I16: =c_FS!I22 -> 31726.469
B17: Operating Profit / (Loss) (EBIT) | E17: =E10+SUM(E12:E16) -> -87735 | F17: =F10+SUM(F12:F16) -> 19454 | G17: =G10+SUM(G12:G16) -> 38449.219 | H17: =H10+SUM(H12:H16) -> 129053.21 | I17: =I10+SUM(I12:I16) -> 237948.52
B18: Operating Profit Margin % | E18: =E17/E8 -> -0.044042481 | F18: =F17/F8 -> 0.0085668211 | G18: =G17/G8 -> 0.015 | H18: =H17/H8 -> 0.045 | I18: =I17/I8 -> 0.075
B19: Depreciation & amortization (add-back) | E19: =-c_FS!E37 -> 57437 | F19: =-c_FS!F37 -> 57218 | G19: =-c_FS!G37 -> 54121.5 | H19: =-c_FS!H37 -> 54385.05 | I19: =-c_FS!I37 -> 54569.535
B20: EBITDA | E20: =E17+E19 -> -30298 | F20: =F17+F19 -> 76672 | G20: =G17+G19 -> 92570.719 | H20: =H17+H19 -> 183438.26 | I20: =I17+I19 -> 292518.06
B21: EBITDA Margin % | E21: =E20/E8 -> -0.015209427 | F21: =F20/F8 -> 0.033763509 | G21: =G20/G8 -> 0.036114148 | H21: =H20/H8 -> 0.063963706 | I21: =I20/I8 -> 0.092200002
B22: Net financial income / (costs) | E22: =c_FS!E58 -> 1686 | F22: =c_FS!F58 -> -1291 | G22: =c_FS!G58 -> -823.9466 | H22: =c_FS!H58 -> 503.59455 | I22: =c_FS!I58 -> 2939.6296
B23: Fair value adjustments & other | E23: =i_Historical!E25 -> -1951 | F23: =i_Historical!F25 -> -3882 | G23: =i_Inputs!G50 -> 0 | H23: =i_Inputs!H50 -> 0 | I23: =i_Inputs!I50 -> 0
B24: Profit / (Loss) Before Income Tax | E24: =E17+SUM(E22:E23) -> -88000 | F24: =F17+SUM(F22:F23) -> 14281 | G24: =G17+SUM(G22:G23) -> 37625.272 | H24: =H17+SUM(H22:H23) -> 129556.81 | I24: =I17+SUM(I22:I23) -> 240888.15
B25: Corporate income tax expense | E25: =i_Historical!E27 -> -14594 | F25: =i_Historical!F27 -> -13361 | G25: =-MAX(0, G24)*i_Inputs!$D$49 -> -8277.5599 | H25: =-MAX(0, H24)*i_Inputs!$D$49 -> -28502.498 | I25: =-MAX(0, I24)*i_Inputs!$D$49 -> -52995.393
B26: Net Profit / (Loss) for the Period | E26: =SUM(E24:E25) -> -102594 | F26: =SUM(F24:F25) -> 920 | G26: =SUM(G24:G25) -> 29347.712 | H26: =SUM(H24:H25) -> 101054.31 | I26: =SUM(I24:I25) -> 187892.76
B27: Net Profit Margin % | E27: =E26/E8 -> -0.051501616 | F27: =F26/F8 -> 0.00040513393 | G27: =G26/G8 -> 0.011449275 | H27: =H26/H8 -> 0.035236968 | I27: =I26/I8 -> 0.059222712
B29: Free Cash Flow and Cash Balance
B31: NOPAT | E31: =o_FS!E17*(1-i_Inputs!$D$49) -> -68433.3 | F31: =o_FS!F17*(1-i_Inputs!$D$49) -> 15174.12 | G31: =o_FS!G17*(1-i_Inputs!$D$49) -> 29990.391 | H31: =o_FS!H17*(1-i_Inputs!$D$49) -> 100661.51 | I31: =o_FS!I17*(1-i_Inputs!$D$49) -> 185599.85
B32: Add: depreciation & amortization | E32: =o_FS!E19 -> 57437 | F32: =o_FS!F19 -> 57218 | G32: =o_FS!G19 -> 54121.5 | H32: =o_FS!H19 -> 54385.05 | I32: =o_FS!I19 -> 54569.535
B33: Less: capex | E33: =-c_FS!E36 -> -24860 | F33: =-c_FS!F36 -> -49348 | G33: =-c_FS!G36 -> -55000 | H33: =-c_FS!H36 -> -55000 | I33: =-c_FS!I36 -> -55000
B34: Less: change in net working capital | E34: =-(c_FS!E31) -> 1370 | F34: =-(c_FS!F31) -> 25578 | G34: =-c_FS!G31 -> 9952.854 | H34: =-c_FS!H31 -> -8598.8857 | I34: =-c_FS!I31 -> 3203.6257
B35: Free Cash Flow to Firm (FCFF) | E35: =SUM(E31:E34) -> -34486.3 | F35: =SUM(F31:F34) -> 48622.12 | G35: =SUM(G31:G34) -> 39064.745 | H35: =SUM(H31:H34) -> 91447.671 | I35: =SUM(I31:I34) -> 188373.01
B37: Opening cash balance | E37: =D39 -> 325013 | F37: =E39 -> 342247 | G37: =F39 -> 357038 | H37: =G39 -> 384660.83 | I37: =H39 -> 465465.84
B38: Add: net cash generated in period | E38: =i_Historical!E32-E37 -> 17234 | F38: =i_Historical!F32-F37 -> 14791 | G38: =G35+G22*(1-i_Inputs!$D$49)+c_FS!G51+c_FS!G50+c_FS!G44+c_FS!G45 -> 27622.832 | H38: =H35+H22*(1-i_Inputs!$D$49)+c_FS!H51+c_FS!H50+c_FS!H44+c_FS!H45 -> 80805.013 | I38: =I35+I22*(1-i_Inputs!$D$49)+c_FS!I51+c_FS!I50+c_FS!I44+c_FS!I45 -> 178810.52
B39: Closing cash & cash equivalents | D39: =i_Inputs!D47 -> 325013 | E39: =SUM(E37:E38) -> 342247 | F39: =SUM(F37:F38) -> 357038 | G39: =SUM(G37:G38) -> 384660.83 | H39: =SUM(H37:H38) -> 465465.84 | I39: =SUM(I37:I38) -> 644276.37
B40: Less: total funded debt outstanding | E40: =-c_FS!E46 -> -138498 | F40: =-c_FS!F46 -> -527 | G40: =-c_FS!G46 -> 0 | H40: =-c_FS!H46 -> 0 | I40: =-c_FS!I46 -> 0
B41: Less: lease liabilities outstanding | E41: =-c_FS!E52 -> -98876 | F41: =-c_FS!F52 -> -107037 | G41: =-c_FS!G52 -> -96764.766 | H41: =-c_FS!H52 -> -85729.304 | I41: =-c_FS!I52 -> -73873.908
B42: Net Cash / (Net Debt) Position | E42: =SUM(E39:E41) -> 104873 | F42: =SUM(F39:F41) -> 249474 | G42: =SUM(G39:G41) -> 287896.07 | H42: =SUM(H39:H41) -> 379736.54 | I42: =SUM(I39:I41) -> 570402.46
B44: End of Worksheet

Sheet Calcs>>

Sheet c_FS
A1: =Contents!$A1 -> Bolt Technology OÜ|Pre-IPO Equity Valuation Model
A2: =Contents!$A2 -> Source: Bolt Technology OÜ Consolidated Annual Report 2024-25 (AS PricewaterhouseCoopers audit)
B4: (EUR '000 unless stated) | E4: =i_Inputs!E4 -> 2024A | F4: =i_Inputs!F4 -> 2025A | G4: =i_Inputs!G4 -> 2026E | H4: =i_Inputs!H4 -> 2027E | I4: =i_Inputs!I4 -> 2028E
E5: =i_Inputs!E5 -> Actual | F5: =i_Inputs!F5 -> Actual | G5: =i_Inputs!G5 -> Estimate | H5: =i_Inputs!H5 -> Estimate | I5: =i_Inputs!I5 -> Estimate
B6: Revenue Breakdown
B8: Ride-hailing revenue | E8: =IF(E$5="Actual",i_Historical!E12,D8*(1+i_Inputs!E8+i_Scenario_Manager!$D10)) -> 1633907 | F8: =IF(F$5="Actual",i_Historical!F12,E8*(1+i_Inputs!F8+i_Scenario_Manager!$D10)) -> 1847432 | G8: =IF(G$5="Actual",i_Historical!G12,F8*(1+i_Inputs!G8+i_Scenario_Manager!$D10)) -> 2069123.8 | H8: =IF(H$5="Actual",i_Historical!H12,G8*(1+i_Inputs!H8+i_Scenario_Manager!$D10)) -> 2296727.5 | I8: =IF(I$5="Actual",i_Historical!I12,H8*(1+i_Inputs!I8+i_Scenario_Manager!$D10)) -> 2526400.2
B9: Food & goods delivery revenue | E9: =IF(E$5="Actual",i_Historical!E13,D9*(1+i_Inputs!E9+i_Scenario_Manager!$D11)) -> 185469 | F9: =IF(F$5="Actual",i_Historical!F13,E9*(1+i_Inputs!F9+i_Scenario_Manager!$D11)) -> 240737 | G9: =IF(G$5="Actual",i_Historical!G13,F9*(1+i_Inputs!G9+i_Scenario_Manager!$D11)) -> 284069.66 | H9: =IF(H$5="Actual",i_Historical!H13,G9*(1+i_Inputs!H9+i_Scenario_Manager!$D11)) -> 329520.81 | I9: =IF(I$5="Actual",i_Historical!I13,H9*(1+i_Inputs!I9+i_Scenario_Manager!$D11)) -> 375653.72
B10: Rental services revenue | E10: =IF(E$5="Actual",i_Historical!E14,D10*(1+i_Inputs!E10+i_Scenario_Manager!$D12)) -> 172678 | F10: =IF(F$5="Actual",i_Historical!F14,E10*(1+i_Inputs!F10+i_Scenario_Manager!$D12)) -> 182685 | G10: =IF(G$5="Actual",i_Historical!G14,F10*(1+i_Inputs!G10+i_Scenario_Manager!$D12)) -> 210087.75 | H10: =IF(H$5="Actual",i_Historical!H14,G10*(1+i_Inputs!H10+i_Scenario_Manager!$D12)) -> 241600.91 | I10: =IF(I$5="Actual",i_Historical!I14,H10*(1+i_Inputs!I10+i_Scenario_Manager!$D12)) -> 270593.02
B11: Total Sales Revenue | E11: =SUM(E8:E10) -> 1992054 | F11: =SUM(F8:F10) -> 2270854 | G11: =SUM(G8:G10) -> 2563281.2 | H11: =SUM(H8:H10) -> 2867849.2 | I11: =SUM(I8:I10) -> 3172646.9
B12: YoY revenue growth rate (%) | E12: =IF(D11=0, 0, E11/D11-1) -> 0 | F12: =IF(E11=0, 0, F11/E11-1) -> 0.13995605 | G12: =IF(F11=0, 0, G11/F11-1) -> 0.12877413 | H12: =IF(G11=0, 0, H11/G11-1) -> 0.11881955 | I12: =IF(H11=0, 0, I11/H11-1) -> 0.10628096
B14: COGS and Opex Breakdown
B16: COGS/ selling expenses | E16: =IF(E$5="Actual",i_Historical!E16,-E$11*i_Inputs!E14+i_Scenario_Manager!$D16) -> -864477 | F16: =IF(F$5="Actual",i_Historical!F16,-F$11*i_Inputs!F14+i_Scenario_Manager!$D16) -> -831240 | G16: =IF(G$5="Actual",i_Historical!G16,-G$11*i_Inputs!G14+i_Scenario_Manager!$D16) -> -909964.84 | H16: =IF(H$5="Actual",i_Historical!H16,-H$11*i_Inputs!H14+i_Scenario_Manager!$D16) -> -1003747.2 | I16: =IF(I$5="Actual",i_Historical!I16,-I$11*i_Inputs!I14+i_Scenario_Manager!$D16) -> -1094563.2
B18: Marketing expenses | E18: =IF(E$5="Actual",i_Historical!E18,-E$11*i_Inputs!E16+i_Scenario_Manager!$D18) -> -795513 | F18: =IF(F$5="Actual",i_Historical!F18,-F$11*i_Inputs!F16+i_Scenario_Manager!$D18) -> -1048370 | G18: =IF(G$5="Actual",i_Historical!G18,-G$11*i_Inputs!G16+i_Scenario_Manager!$D18) -> -1153476.6 | H18: =IF(H$5="Actual",i_Historical!H18,-H$11*i_Inputs!H16+i_Scenario_Manager!$D18) -> -1218835.9 | I18: =IF(I$5="Actual",i_Historical!I18,-I$11*i_Inputs!I16+i_Scenario_Manager!$D18) -> -1269058.8
B19: Research and development expenses | E19: =IF(E$5="Actual",i_Historical!E19,-E$11*i_Inputs!E17+i_Scenario_Manager!$D19) -> -107877 | F19: =IF(F$5="Actual",i_Historical!F19,-F$11*i_Inputs!F17+i_Scenario_Manager!$D19) -> -127580 | G19: =IF(G$5="Actual",i_Historical!G19,-G$11*i_Inputs!G17+i_Scenario_Manager!$D19) -> -128164.06 | H19: =IF(H$5="Actual",i_Historical!H19,-H$11*i_Inputs!H17+i_Scenario_Manager!$D19) -> -143392.46 | I19: =IF(I$5="Actual",i_Historical!I19,-I$11*i_Inputs!I17+i_Scenario_Manager!$D19) -> -158632.35
B20: General and administrative expenses | E20: =IF(E$5="Actual",i_Historical!E20,-E$11*i_Inputs!E18+i_Scenario_Manager!$D20) -> -319933 | F20: =IF(F$5="Actual",i_Historical!F20,-F$11*i_Inputs!F18+i_Scenario_Manager!$D20) -> -253032 | G20: =IF(G$5="Actual",i_Historical!G20,-G$11*i_Inputs!G18+i_Scenario_Manager!$D20) -> -307593.75 | H20: =IF(H$5="Actual",i_Historical!H20,-H$11*i_Inputs!H18+i_Scenario_Manager!$D20) -> -344141.9 | I20: =IF(I$5="Actual",i_Historical!I20,-I$11*i_Inputs!I18+i_Scenario_Manager!$D20) -> -380717.63
B21: Other operating expenses | E21: =IF(E$5="Actual",i_Historical!E21,-E$11*i_Inputs!E19+i_Scenario_Manager!$D21) -> -8913 | F21: =IF(F$5="Actual",i_Historical!F21,-F$11*i_Inputs!F19+i_Scenario_Manager!$D21) -> -13131 | G21: =IF(G$5="Actual",i_Historical!G21,-G$11*i_Inputs!G19+i_Scenario_Manager!$D21) -> -51265.625 | H21: =IF(H$5="Actual",i_Historical!H21,-H$11*i_Inputs!H19+i_Scenario_Manager!$D21) -> -57356.984 | I21: =IF(I$5="Actual",i_Historical!I21,-I$11*i_Inputs!I19+i_Scenario_Manager!$D21) -> -63452.939
B22: Other operating income | E22: =IF(E$5="Actual",i_Historical!E22,E$11*i_Inputs!E20+i_Scenario_Manager!$D22) -> 16924 | F22: =IF(F$5="Actual",i_Historical!F22,F$11*i_Inputs!F20+i_Scenario_Manager!$D22) -> 21953 | G22: =IF(G$5="Actual",i_Historical!G22,G$11*i_Inputs!G20+i_Scenario_Manager!$D22) -> 25632.812 | H22: =IF(H$5="Actual",i_Historical!H22,H$11*i_Inputs!H20+i_Scenario_Manager!$D22) -> 28678.492 | I22: =IF(I$5="Actual",i_Historical!I22,I$11*i_Inputs!I20+i_Scenario_Manager!$D22) -> 31726.469
B23: Total Operating Costs | E23: =SUM(E18:E22) -> -1215312 | F23: =SUM(F18:F22) -> -1420160 | G23: =SUM(G18:G22) -> -1614867.2 | H23: =SUM(H18:H22) -> -1735048.8 | I23: =SUM(I18:I22) -> -1840135.2
B24: % of sales revenue | E24: =-E23/E11 -> 0.61007985 | F24: =-F23/F11 -> 0.62538587 | G24: =-G23/G11 -> 0.63 | H24: =-H23/H11 -> 0.605 | I24: =-I23/I11 -> 0.58
B26: Working Capital Schedule
B28: Trade and other receivables | E28: =IF(E$5="Actual",i_Historical!E33,E11*i_Inputs!E24/365) -> 100732 | F28: =IF(F$5="Actual",i_Historical!F33,F11*i_Inputs!F24/365) -> 127467 | G28: =IF(G$5="Actual",i_Historical!G33,G11*i_Inputs!G24/365) -> 140453.77 | H28: =IF(H$5="Actual",i_Historical!H33,H11*i_Inputs!H24/365) -> 157142.42 | I28: =IF(I$5="Actual",i_Historical!I33,I11*i_Inputs!I24/365) -> 173843.67
B29: Trade and other payables | E29: =IF(E$5="Actual",i_Historical!E40,-c_FS!E16*i_Inputs!E25/365) -> 136657 | F29: =IF(F$5="Actual",i_Historical!F40,-c_FS!F16*i_Inputs!F25/365) -> 188970 | G29: =IF(G$5="Actual",i_Historical!G40,-c_FS!G16*i_Inputs!G25/365) -> 211909.62 | H29: =IF(H$5="Actual",i_Historical!H40,-c_FS!H16*i_Inputs!H25/365) -> 219999.39 | I29: =IF(I$5="Actual",i_Historical!I40,-c_FS!I16*i_Inputs!I25/365) -> 239904.26
B30: Net Working Capital (NWC) | D30: =i_Inputs!$D$26 -> -34555 | E30: =E28-E29 -> -35925 | F30: =F28-F29 -> -61503 | G30: =G28-G29 -> -71455.854 | H30: =H28-H29 -> -62856.968 | I30: =I28-I29 -> -66060.594
B31: Change in net working capital (ΔNWC) | E31: =E30-D30 -> -1370 | F31: =F30-E30 -> -25578 | G31: =G30-F30 -> -9952.854 | H31: =H30-G30 -> 8598.8857 | I31: =I30-H30 -> -3203.6257
B33: Fixed Asset Schedule
B35: Opening fixed assets (PP&E + ROU) | E35: =D39 -> 209987 | F35: =E39 -> 189638 | G35: =F39 -> 180405 | H35: =G39 -> 181283.5 | I35: =H39 -> 181898.45
B36: Add: capital expenditures | E36: =IF(E$5="Actual",-i_Historical!E57,i_Inputs!E28) -> 24860 | F36: =IF(F$5="Actual",-i_Historical!F57,i_Inputs!F28) -> 49348 | G36: =IF(G$5="Actual",-i_Historical!G57,i_Inputs!G28) -> 55000 | H36: =IF(H$5="Actual",-i_Historical!H57,i_Inputs!H28) -> 55000 | I36: =IF(I$5="Actual",-i_Historical!I57,i_Inputs!I28) -> 55000
B37: Less: depreciation & amortization | E37: =IF(E$5="Actual",-i_Historical!E56,-E35*i_Inputs!$D$29) -> -57437 | F37: =IF(F$5="Actual",-i_Historical!F56,-F35*i_Inputs!$D$29) -> -57218 | G37: =IF(G$5="Actual",-i_Historical!G56,-G35*i_Inputs!$D$29) -> -54121.5 | H37: =IF(H$5="Actual",-i_Historical!H56,-H35*i_Inputs!$D$29) -> -54385.05 | I37: =IF(I$5="Actual",-i_Historical!I56,-I35*i_Inputs!$D$29) -> -54569.535
B38: Add: ROU fleet additions / other fixed asset movements | E38: =IF(E$5="Actual",i_Historical!E36-SUM(E35:E37),i_Inputs!E31) -> 12228 | F38: =IF(F$5="Actual",i_Historical!F36-SUM(F35:F37),i_Inputs!F31) -> -1363 | G38: =IF(G$5="Actual",i_Historical!G36-SUM(G35:G37),i_Inputs!G31) -> 0 | H38: =IF(H$5="Actual",i_Historical!H36-SUM(H35:H37),i_Inputs!H31) -> 0 | I38: =IF(I$5="Actual",i_Historical!I36-SUM(I35:I37),i_Inputs!I31) -> 0
B39: Closing fixed assets (PP&E + ROU) | D39: =i_Inputs!D30 -> 209987 | E39: =SUM(E35:E38) -> 189638 | F39: =SUM(F35:F38) -> 180405 | G39: =SUM(G35:G38) -> 181283.5 | H39: =SUM(H35:H38) -> 181898.45 | I39: =SUM(I35:I38) -> 182328.92
B41: Debt & Financing Obligations
B43: Opening debt & convertible bond balance | E43: =D46 -> 139715 | F43: =E46 -> 138498 | G43: =F46 -> 527 | H43: =G46 -> 0 | I43: =H46 -> 0
B44: Add: drawdowns | E44: =IF(E$5="Actual",0,MAX(0,N(i_Inputs!E36))) -> 0 | F44: =IF(F$5="Actual",0,MAX(0,N(i_Inputs!F36))) -> 0 | G44: =IF(G$5="Actual",0,MAX(0,N(i_Inputs!G36))) -> 0 | H44: =IF(H$5="Actual",0,MAX(0,N(i_Inputs!H36))) -> 0 | I44: =IF(I$5="Actual",0,MAX(0,N(i_Inputs!I36))) -> 0
B45: Less: repayments / derecognition via equity conversion | E45: =IF(E$5="Actual",i_Historical!E41-SUM(E43:E44), MIN(0,N(i_Inputs!E36))) -> -1217 | F45: =IF(F$5="Actual",i_Historical!F41-SUM(F43:F44), MIN(0,N(i_Inputs!F36))) -> -137971 | G45: =IF(G$5="Actual",i_Historical!G41-SUM(G43:G44), MIN(0,N(i_Inputs!G36))) -> -527 | H45: =IF(H$5="Actual",i_Historical!H41-SUM(H43:H44), MIN(0,N(i_Inputs!H36))) -> 0 | I45: =IF(I$5="Actual",i_Historical!I41-SUM(I43:I44), MIN(0,N(i_Inputs!I36))) -> 0
B46: Closing debt balance | D46: =i_Inputs!D37 -> 139715 | E46: =SUM(E43:E45) -> 138498 | F46: =SUM(F43:F45) -> 527 | G46: =SUM(G43:G45) -> 0 | H46: =SUM(H43:H45) -> 0 | I46: =SUM(I43:I45) -> 0
B48: Opening lease liabilities balance | E48: =D52 -> 96820 | F48: =E52 -> 98876 | G48: =F52 -> 107037 | H48: =G52 -> 96764.766 | I48: =H52 -> 85729.304
B49: Add: ROU fleet additions / other lease movements | E49: =E38 -> 12228 | F49: =F38 -> -1363 | G49: =G38 -> 0 | H49: =H38 -> 0 | I49: =I38 -> 0
B50: Add: lease interest accretion | E50: =-E55 -> 7193.726 | F50: =-F55 -> 7346.4868 | G50: =-G55 -> 7952.8491 | H50: =-H55 -> 7189.6221 | I50: =-I55 -> 6369.6873
B51: Less: lease cash payments | E51: =IF(E$5="Actual",i_Historical!E42-SUM(E48:E50),-i_Inputs!E41) -> -17365.726 | F51: =IF(F$5="Actual",i_Historical!F42-SUM(F48:F50),-i_Inputs!F41) -> 2177.5132 | G51: =IF(G$5="Actual",i_Historical!G42-SUM(G48:G50),-i_Inputs!G41) -> -18225.083 | H51: =IF(H$5="Actual",i_Historical!H42-SUM(H48:H50),-i_Inputs!H41) -> -18225.083 | I51: =IF(I$5="Actual",i_Historical!I42-SUM(I48:I50),-i_Inputs!I41) -> -18225.083
B52: Closing lease liabilities balance | D52: =i_Inputs!D40 -> 96820 | E52: =SUM(E48:E51) -> 98876 | F52: =SUM(F48:F51) -> 107037 | G52: =SUM(G48:G51) -> 96764.766 | H52: =SUM(H48:H51) -> 85729.304 | I52: =SUM(I48:I51) -> 73873.908
...

Sheet Input>>

Sheet i_Scenario_Manager
A1: =Contents!$A1 -> Bolt Technology OÜ|Pre-IPO Equity Valuation Model
A2: =Contents!$A2 -> Source: Bolt Technology OÜ Consolidated Annual Report 2024-25 (AS PricewaterhouseCoopers audit)
B6: Selected Case | C6: 3 | E6: =D6+1 -> 1 | F6: =E6+1 -> 2 | G6: =F6+1 -> 3 | H6: =G6+1 -> 4 | I6: =H6+1 -> 5
B8: Revenue
B10: Ride-hailing revenue | C10: (+/-)% | D10: {=INDEX(E10:J10,$C$6)} -> 0 | E10: -0.05 | F10: -0.025 | G10: 0 | H10: 0.025 | I10: 0.05
B11: Food & delivery | C11: (+/-)% | D11: {=INDEX(E11:J11,$C$6)} -> 0 | E11: -0.05 | F11: -0.025 | G11: 0 | H11: 0.025 | I11: 0.05
B12: Rental & drive revenue | C12: (+/-)% | D12: {=INDEX(E12:J12,$C$6)} -> 0 | E12: -0.05 | F12: -0.025 | G12: 0 | H12: 0.025 | I12: 0.05
B14: COGS and Opex
B16: COGS / selling expenses | C16: (+/-)% | D16: {=INDEX(E16:J16,$C$6)} -> 0 | E16: -0.05 | F16: -0.025 | G16: 0 | H16: 0.025 | I16: 0.05
B18: Marketing spend | C18: (+/-)% | D18: {=INDEX(E18:J18,$C$6)} -> 0 | E18: -0.05 | F18: -0.025 | G18: 0 | H18: 0.025 | I18: 0.05
B19: R&D spend | C19: (+/-)% | D19: {=INDEX(E19:J19,$C$6)} -> 0 | E19: -0.05 | F19: -0.025 | G19: 0 | H19: 0.025 | I19: 0.05
B20: G&A | C20: (+/-)% | D20: {=INDEX(E20:J20,$C$6)} -> 0 | E20: -0.05 | F20: -0.025 | G20: 0 | H20: 0.025 | I20: 0.05
B21: Other operating expenses | C21: (+/-)% | D21: {=INDEX(E21:J21,$C$6)} -> 0 | E21: -0.05 | F21: -0.025 | G21: 0 | H21: 0.025 | I21: 0.05
B22: Other operating income | C22: (+/-)% | D22: {=INDEX(E22:J22,$C$6)} -> 0 | E22: -0.05 | F22: -0.025 | G22: 0 | H22: 0.025 | I22: 0.05
B24: WACC & Terminal Growth
B26: Weighted Average Cost of Capital (WACC) | C26: (+/-)% | D26: {=INDEX(E26:J26,$C$6)} -> 0 | E26: -0.05 | F26: -0.025 | G26: 0 | H26: 0.025 | I26: 0.05
B27: Terminal Growth Rate (g) | C27: (+/-)% | D27: {=INDEX(E27:J27,$C$6)} -> 0 | E27: -0.05 | F27: -0.025 | G27: 0 | H27: 0.025 | I27: 0.05
B29: Equity Dilution
B31: Target Primary Capital Raised at IPO | C31: (+/-)% | D31: {=INDEX(E31:J31,$C$6)} -> 0 | E31: -0.05 | F31: -0.025 | G31: 0 | H31: 0.025 | I31: 0.05
B33: End of Worksheet

Sheet i_Inputs
A1: =Contents!$A1 -> Bolt Technology OÜ|Pre-IPO Equity Valuation Model
A2: =Contents!$A2 -> Source: Bolt Technology OÜ Consolidated Annual Report 2024-25 (AS PricewaterhouseCoopers audit)
C4: Unit | E4: =i_Historical!E4 -> 2024A | F4: =i_Historical!F4 -> 2025A | G4: =i_Historical!G4 -> 2026E | H4: =i_Historical!H4 -> 2027E | I4: =i_Historical!I4 -> 2028E | J4: Benchmark/ Source
E5: =i_Historical!E5 -> Actual | F5: =i_Historical!F5 -> Actual | G5: =i_Historical!G5 -> Estimate | H5: =i_Historical!H5 -> Estimate | I5: =i_Historical!I5 -> Estimate
B6: Growth Drivers
B8: Ride-hailing revenue | C8: % | G8: 0.12 | H8: 0.11 | I8: 0.1 | J8: Mature platform equilibrium; AV pilot additions in EU
B9: Food & delivery | C9: % | G9: 0.18 | H9: 0.16 | I9: 0.14 | J9: Bolt Plus subscriber adoption (already >20% GMV in core mkts)
B10: Rental & drive revenue | C10: % | G10: 0.15 | H10: 0.15 | I10: 0.12 | J10: Micromobility tender wins (UK, London e-bikes, Brussels)
B12: COGS & Opex Assumptions (% of Revenue)
B14: COGS / selling expenses | C14: % | G14: 0.355 | H14: 0.35 | I14: 0.345 | J14: Down from 36.6% in 2025 due to transport cost optimization
B16: Marketing spend | C16: % | G16: 0.45 | H16: 0.425 | I16: 0.4 | J16: Current is 46.2%; opening post-expansion normalization
B17: R&D spend | C17: % | G17: 0.05 | H17: 0.05 | I17: 0.05 | J17: Sustained tech talent density & AV integration with Pony.ai
B18: G&A | C18: % | G18: 0.12 | H18: 0.12 | I18: 0.12 | J18: Corporate overhead fixed cost operating leverage
B19: Other operating expenses | C19: % | G19: 0.02 | H19: 0.02 | I19: 0.02 | J19: Receivable discounts & write-offs
B20: Other operating income | C20: % | G20: 0.01 | H20: 0.01 | I20: 0.01 | J20: Consistent with historical 2025 other income
B22: Working Capital & Capex
B24: Trade receivables | C24: days | G24: 20 | H24: 20 | I24: 20 | J24: Consistent with historical 2025 net receivables (~€127M)
B25: Trade payables | C25: days | G25: 85 | H25: 80 | I25: 80 | J25: Consistent with historical payment terms with fleet/suppliers
B26: ="Closing working capital balance as of " & TEXT(i_Historical!$C$7 - 1, "dd-mm-yyyy") -> Closing working capital balance as of 31-12-2023 | C26: EUR '000 | D26: -34555 | J26: Bolt Technology OÜ Consolidated Annual Report 2024
B28: PP&E capex | C28: EUR '000 | G28: 55000 | H28: 55000 | I28: 55000 | J28: (€55.0M/yr) to fund recurring micromobility fleet renewals (Note 8 notes an existing €15.7M purchase commitment)
B29: D&A rate p.a, blended | C29: % | D29: 0.3 | J29: Reflects 3-8 yr scooter life and 2-3 yr vehicle lease life
B30: ="Closing PPE and ROU balance as of " & TEXT(i_Historical!$C$7 - 1, "dd-mm-yyyy") -> Closing PPE and ROU balance as of 31-12-2023 | C30: EUR '000 | D30: 209987 | J30: Bolt Technology OÜ Consolidated Annual Report 2024
B31: ROU fleet additions / other fixed asset movements | C31: EUR '000 | J31: Historical periods solve for other fixed-asset movements so the roll-forward ties to audited closing PP&E + ROU. Forecast periods use the explicit ROU-additions control input.
B33: Debt & Financing Obligations
B35: Cost of debt p.a | C35: % | D35: 0.045 | J35: 3-Month EURIBOR (~2.65%) + 175–250 bps margin
B36: Net debt drawdown / (repayment) | C36: EUR '000 | G36: -527 | J36: Placeholder: enter positive value for debt drawdown / negative for repayment
B37: ="Closing debt balance as of "& TEXT(i_Historical!$C$7 - 1, "dd-mm-yyyy") -> Closing debt balance as of 31-12-2023 | C37: EUR '000 | D37: 139715 | J37: Bolt Technology OÜ Consolidated Annual Report 2024
B39: Effective incremental borrowing rate p.a | C39: % | D39: 0.0743 | J39: Bolt Technology OÜ Consolidated Annual Report 2025
B40: ="Closing lease liabilities as of "& TEXT(i_Historical!$C$7 - 1, "dd-mm-yyyy") -> Closing lease liabilities as of 31-12-2023 | C40: EUR '000 | D40: 96820 | J40: Bolt Technology OÜ Consolidated Annual Report 2024
B41: Lease cash payments | C41: EUR '000 | G41: =PMT($D$39,$D$42,-c_FS!$F$52) -> 18225.083 | H41: =PMT($D$39,$D$42,-c_FS!$F$52) -> 18225.083 | I41: =PMT($D$39,$D$42,-c_FS!$F$52) -> 18225.083 | J41: Periodic fixed payment (PMT)
B42: Payment period | C42: Years | D42: 8
B44: Other Assumptions
B46: Interest yield on cash p.a | C46: % | D46: 0.02 | J46: Bolt had over €206M in money market funds (MMFs) and €134M in tier-1 bank accounts (rated Aa3/Baa1 by Moody’s) (Note 5)
B47: ="Closing cash balance as of "& TEXT(i_Historical!$C$7 - 1, "dd-mm-yyyy") -> Closing cash balance as of 31-12-2023 | C47: EUR '000 | D47: 325013 | J47: Bolt Technology OÜ Consolidated Annual Report 2024
B49: Effective corporate tax rate | C49: % | D49: 0.22
B50: Other non-recurring instruments | C50: EUR '000 | G50: 0 | H50: 0 | I50: 0
B52: Valuation and IPO Capital Market Assumptions
B54: Weighted Average Cost of Capital (WACC) | C54: % | D54: 0.105 | J54: Manual override - used only when CAPM/WACC switch = 0
B55: WACC selection switch (1 = CAPM build-up, 0 = manual override) | C55: Flag | D55: 1 | J55: Feeds o_Valuation selected WACC; set to 0 to use manual WACC in D54
B57: Terminal Growth Rate | C57: % | D57: 0.04 | J57: Long-term GDP + growth for urban shared mobility
...

Sheet i_Historical
A1: =Contents!$A1 -> Bolt Technology OÜ|Pre-IPO Equity Valuation Model
A2: =Contents!$A2 -> Source: Bolt Technology OÜ Consolidated Annual Report 2024-25 (AS PricewaterhouseCoopers audit)
E3: =C7 -> 45292 | F3: =EDATE(E3,12) -> 45658 | G3: =EDATE(F3,12) -> 46023 | H3: =EDATE(G3,12) -> 46388 | I3: =EDATE(H3,12) -> 46753
C4: Unit | E4: =YEAR(E3)&IF(E5="Actual", "A", IF(E5="Estimate","E",_xleta.NA)) -> 2024A | F4: =YEAR(F3)&IF(F5="Actual", "A", IF(F5="Estimate","E",_xleta.NA)) -> 2025A | G4: =YEAR(G3)&IF(G5="Actual", "A", IF(G5="Estimate","E",_xleta.NA)) -> 2026E | H4: =YEAR(H3)&IF(H5="Actual", "A", IF(H5="Estimate","E",_xleta.NA)) -> 2027E | I4: =YEAR(I3)&IF(I5="Actual", "A", IF(I5="Estimate","E",_xleta.NA)) -> 2028E | K4: YoY Change (€) | L4: YoY Change (%) | M4: Source Note
E5: =IF(E3<$C$8, "Actual", "Estimate") -> Actual | F5: =IF(F3<$C$8, "Actual", "Estimate") -> Actual | G5: =IF(G3<$C$8, "Actual", "Estimate") -> Estimate | H5: =IF(H3<$C$8, "Actual", "Estimate") -> Estimate | I5: =IF(I3<$C$8, "Actual", "Estimate") -> Estimate
B6: Historical Consolidated Statement of Financial Position (click to follow source)
B7: Model Start Year | C7: 45292
B8: Forecast Start Year | C8: 46023
B10: Income Statement
B12: Ride-hailing revenue | C12: EUR '000 | E12: 1633907 | F12: 1847432 | K12: =F12-E12 -> 213525 | L12: =IF(E12=0,"N/a",K12/ABS(E12)) -> 0.13068369 | M12: Note 17
B13: Food & goods delivery revenue | C13: EUR '000 | E13: 185469 | F13: 240737 | K13: =F13-E13 -> 55268 | L13: =IF(E13=0,"N/a",K13/ABS(E13)) -> 0.2979905 | M13: Note 17
B14: Rental services revenue (Micromobility & Drive) | C14: EUR '000 | E14: 172678 | F14: 182685 | K14: =F14-E14 -> 10007 | L14: =IF(E14=0,"N/a",K14/ABS(E14)) -> 0.057951795 | M14: Note 17
B15: Total Sales Revenue | C15: EUR '000 | E15: 1992054 | F15: 2270854 | K15: =F15-E15 -> 278800 | L15: =IF(E15=0,"N/a",K15/ABS(E15)) -> 0.13995605 | M15: Note 17
B16: COGS/ selling expenses | C16: EUR '000 | E16: -864477 | F16: -831240 | K16: =F16-E16 -> 33237 | L16: =IF(E16=0,"N/a",K16/ABS(E16)) -> 0.038447524 | M16: Note 20
B17: Gross Profit | C17: EUR '000 | E17: 1127577 | F17: 1439614 | K17: =F17-E17 -> 312037 | L17: =IF(E17=0,"N/a",K17/ABS(E17)) -> 0.27673232 | M17: P&L
B18: Marketing expenses | C18: EUR '000 | E18: -795513 | F18: -1048370 | K18: =F18-E18 -> -252857 | L18: =IF(E18=0,"N/a",K18/ABS(E18)) -> -0.31785401 | M18: Note 22
B19: Research and development expenses | C19: EUR '000 | E19: -107877 | F19: -127580 | K19: =F19-E19 -> -19703 | L19: =IF(E19=0,"N/a",K19/ABS(E19)) -> -0.1826432 | M19: Note 21
B20: General and administrative expenses | C20: EUR '000 | E20: -319933 | F20: -253032 | K20: =F20-E20 -> 66901 | L20: =IF(E20=0,"N/a",K20/ABS(E20)) -> 0.20910941 | M20: Note 23
B21: Other operating expenses | C21: EUR '000 | E21: -8913 | F21: -13131 | K21: =F21-E21 -> -4218 | L21: =IF(E21=0,"N/a",K21/ABS(E21)) -> -0.47324133 | M21: Note 19
B22: Other operating income | C22: EUR '000 | E22: 16924 | F22: 21953 | K22: =F22-E22 -> 5029 | L22: =IF(E22=0,"N/a",K22/ABS(E22)) -> 0.29715197 | M22: Note 18
B23: Operating Profit / (Loss) (EBIT) | C23: EUR '000 | E23: -87735 | F23: 19454 | K23: =F23-E23 -> 107189 | L23: =IF(E23=0,"N/a",K23/ABS(E23)) -> 1.2217359 | M23: P&L
... B28: Net Profit / (Loss) for the period | C28: EUR '000 | E28: -102594 | F28: 920 | K28: =F28-E28 -> 103514 | L28: =IF(E28=0,"N/a",K28/ABS(E28)) -> 1.0089674 | M28: P&L
B30: Balance Sheet & Capitalization Actuals
B32: Cash and cash equivalents | C32: EUR '000 | E32: 342247 | F32: 357038 | K32: =F32-E32 -> 14791 | L32: =IF(E32=0,"N/a",K32/ABS(E32)) -> 0.043217325 | M32: Note 5
B33: Trade and other receivables and prepayments | C33: EUR '000 | E33: 100732 | F33: 127467 | K33: =F33-E33 -> 26735 | L33: =IF(E33=0,"N/a",K33/ABS(E33)) -> 0.26540722 | M33: Note 6
B34: Other current assets | C34: EUR '000 | E34: =E35-SUM(E32:E33) -> 14105 | F34: =F35-SUM(F32:F33) -> 16675 | G34: =G35-SUM(G32:G33) -> 0 | H34: =H35-SUM(H32:H33) -> 0 | I34: =I35-SUM(I32:I33) -> 0 | K34: =F34-E34 -> 2570 | L34: =IF(E34=0,"N/a",K34/ABS(E34)) -> 0.18220489
B35: Total current assets | C35: EUR '000 | E35: 457084 | F35: 501180 | K35: =F35-E35 -> 44096 | L35: =IF(E35=0,"N/a",K35/ABS(E35)) -> 0.096472421 | M35: Balance Sheet
B36: Fixed asset (PPE + ROU) | C36: EUR '000 | E36: 189638 | F36: 180405 | K36: =F36-E36 -> -9233 | L36: =IF(E36=0,"N/a",K36/ABS(E36)) -> -0.048687499 | M36: Note 8 & 9
B37: Other non-current assets | C37: EUR '000 | E37: =E38-E36 -> 134298 | F37: =F38-F36 -> 150910 | G37: =G38-G36 -> 0 | H37: =H38-H36 -> 0 | I37: =I38-I36 -> 0 | K37: =F37-E37 -> 16612 | L37: =IF(E37=0,"N/a",K37/ABS(E37)) -> 0.12369507
B38: Total non-current assets | C38: EUR '000 | E38: 323936 | F38: 331315 | K38: =F38-E38 -> 7379 | L38: =IF(E38=0,"N/a",K38/ABS(E38)) -> 0.022779191 | M38: Balance Sheet
B39: Total Assets | C39: EUR '000 | E39: 781020 | F39: 832495 | K39: =F39-E39 -> 51475 | L39: =IF(E39=0,"N/a",K39/ABS(E39)) -> 0.065907403 | M39: Balance Sheet
B40: Trade and other payables | C40: EUR '000 | E40: 136657 | F40: 188970 | K40: =F40-E40 -> 52313 | L40: =IF(E40=0,"N/a",K40/ABS(E40)) -> 0.38280513 | M40: Note 11
B41: Funded debt / convertible bonds | C41: EUR '000 | E41: 138498 | F41: 527 | K41: =F41-E41 -> -137971 | L41: =IF(E41=0,"N/a",K41/ABS(E41)) -> -0.99619489 | M41: Note 12
B42: Lease obligations (current + non-current) | C42: EUR '000 | E42: 98876 | F42: 107037 | K42: =F42-E42 -> 8161 | L42: =IF(E42=0,"N/a",K42/ABS(E42)) -> 0.082537724 | M42: Note 14
B43: Balance sheet provisions (legal + tax) | C43: EUR '000 | E43: 185296 | F43: 155073 | K43: =F43-E43 -> -30223 | L43: =IF(E43=0,"N/a",K43/ABS(E43)) -> -0.1631066 | M43: Note 15
B44: Other liabilities | C44: EUR '000 | E44: =E45-SUM(E40:E43) -> 20454 | F44: =F45-SUM(F40:F43) -> 20904 | G44: =G45-SUM(G40:G43) -> 0 | H44: =H45-SUM(H40:H43) -> 0 | I44: =I45-SUM(I40:I43) -> 0 | K44: =F44-E44 -> 450 | L44: =IF(E44=0,"N/a",K44/ABS(E44)) -> 0.022000587
B45: Total Liabilities | C45: EUR '000 | E45: 579781 | F45: 472511 | K45: =F45-E45 -> -107270 | L45: =IF(E45=0,"N/a",K45/ABS(E45)) -> -0.18501814 | M45: Balance Sheet
B46: Total Equity | C46: EUR '000 | E46: 201239 | F46: 359984 | K46: =F46-E46 -> 158745 | L46: =IF(E46=0,"N/a",K46/ABS(E46)) -> 0.78883815 | M46: Balance Sheet
A47: =IF(SUM(E47:I47)<>0,"Error","OK") -> OK | B47: BS Check | C47: Check | E47: =E39-(E45+E46) -> 0 | F47: =F39-(F45+F46) -> 0 | G47: =G39-(G45+G46) -> 0 | H47: =H39-(H45+H46) -> 0 | I47: =I39-(I45+I46) -> 0
B49: Shares outstanding (registered) | C49: Thousands | E49: 28823 | F49: 28823 | K49: =F49-E49 -> 0 | L49: =IF(E49=0,"N/a",K49/ABS(E49)) -> 0 | M49: Note 16
...
